Workbook
Name CMMVersion: OOC!#REF!
Name dim_type: #REF!
Name dim_types: #REF!
Name gauging: #REF!
Name insp_meth: #REF!

Sheet OQC
A1: Enhanced Cpk Data Sheet - Enclosures MD
B2: Rev 4.3 | V2: Instructions | Y2: 없는 툴#캐비티 | AK2: {=_xlfn.LET(_xlpm.src,TOCOL(LEFT(AK10:BP10,3),1), _xlpm.obs,_xlfn._xlws.FILTER(_xlpm.src,_xlpm.src<>""), _xlpm.tools,_xlfn._xlws.SORT(_xlfn.UNIQUE(LEFT(_xlpm.obs,1))), _xlpm.all,TOCOL(_xlpm.tools&"#"&_xlfn.SEQUENCE(1,4),1), _xlpm.miss,_xlfn._xlws.FILTER(_xlpm.all,ISNA(MATCH(_xlpm.all,_xlpm.obs,0))), IFERROR(TRANSPOSE(_xlpm.miss),""))}
B4: Part Number : | D4: 817-11233 | F4: Supplier : | H4: Dpamstech | O4: Tool # / Build / DOE Name : | R4: @ Tool / MP | Y4: 들어간 툴#캐비티 | AK4: {=IFERROR(TRANSPOSE(_xlfn._xlws.SORT(_xlfn.UNIQUE(TRANSPOSE(LEFT(_xlfn._xlws.FILTER(AK10:BP10,AK10:BP10<>""),3))))),"")}
B5: Part Description : | D5: X Carrier | F5: Inspector : | H5: @@@ | O5: Notes/Comments : | Y5: 들어간 툴 | AK5: {=IFERROR(TRANSPOSE(_xlfn._xlws.SORT(_xlfn.UNIQUE(TRANSPOSE(LEFT(_xlfn._xlws.FILTER(AK10:BP10,AK10:BP10<>""),1))))),"")}
B6: Revision : | D6: 7 | F6: Date : | H6: 측정일 : 25@@@@ / 사출일 :25@@@@ | O6: CMM/OMM Program version : | R6: MP | Y6: 들어간 생산일
B8: DRAWING SPECIFICATIONS | O8: CALCULATED RESULTS | AG8: DO NOT DELETE COLUMNS
B9: FAI | C9: SPC | H9: (USL for one sided spec) | I9: (LSL for one sided spec) | Z9: Tolerance needed to hit target Cpk | AB9: Cp* = | AC9: 1.5
D10: Description | E10: Target Cpk | F10: Dimension Type | G10: Nominal | H10: TOL+ | I10: TOL- | J10: Inspection Method | K10: 100% Gauged | L10: USL | M10: LSL | O10: Maximum | P10: Minimum | Q10: Mean | R10: Std Dev | S10: Cp | T10: Ca | U10: Ca Level | V10: UCPK | W10: LCPK | X10: Cpk | Y10: Yield | Z10: +Tol => Cpk* | AA10: -Tol => Cpk* | AB10: Mean Shift | AC10: Tol Range => Cp* | AD10: Normality Test | AE10: Normality Result | AF10: Notes
A11: 1 | B11: 4-1-a | C11: D | D11: Height | E11: 1.5 | F11: Tolerance | G11: 0.5 | H11: 0.01 | I11: -0.01 | J11: OMM | K11: NO | L11: =IF(AND(G11="",H11=""),"",IF(G11="",H11,G11+H11)) -> 0.51 | M11: =IF(AND(G11="",I11=""),"",IF(G11="",I11,G11+I11)) -> 0.49 | O11: =IF(OR($AK11="",ISNUMBER($AK11)=FALSE),"",MAX(AK11:BP11)) | P11: =IF(OR($AK11="",ISNUMBER($AK11)=FALSE),"",MIN(AK11:BP11)) | Q11: =IF(OR($AK11="",ISNUMBER($AK11)=FALSE),"",AVERAGE(AK11:BP11)) | R11: =IF(OR($AK11="",ISNUMBER($AK11)=FALSE),"",STDEV(AK11:BP11)) | S11: =IF(OR($AK11="",ISNUMBER($AK11)=FALSE),"",IF(AND(G11="",I11=""),V11,IF(AND(G11="",H11=""),W11,(H11+ABS(I11))/(6*R11)))) | T11: =IF(OR($AK11="",ISNUMBER($AK11)=FALSE),"",IF(AND($F11="Tolerance",$G11<>""),($Q11-$G11)/(($L11-$M11)/2),IF(AND($F11="GD&T",$H11<>""),$Q11/$H11,""))) | U11: =IF($T11="","",IF(ABS($T11)<=0.125, "Level A",IF(AND(ABS($T11)>0.125,ABS($T11)<=0.25), "Level B",IF(AND(ABS($T11)>0.25,ABS($T11)<=0.5), "Level C", IF(ABS($T11)>0.5, "Level D"))))) | V11: =IF(OR($AK11="",ISNUMBER($AK11)=FALSE),"",IF(H11="","",(L11-Q11)/(3*R11))) | W11: =IF(OR($AK11="",ISNUMBER($AK11)=FALSE),"",IF(I11="","",(Q11-M11)/(3*R11))) | X11: =IF(OR($AK11="",ISNUMBER($AK11)=FALSE),"",IF(AND(G11=0,I11=0),((H11)-(Q11))/(3*R11),MIN(V11:W11))) | Y11: =IF(OR($AK11="",ISNUMBER($AK11)=FALSE),"",IF(AND(G11=0,I11=0),NORMSDIST(3*X11),NORMSDIST(3*X11)+NORMSDIST(6*S11-3*X11)-1)) | Z11: =IF($Q11="","",IF(F11="Tolerance",IF(($E11*3*R11+Q11)-G11<H11,"",($E11*3*R11+Q11)-G11),IF(OR(F11="GD&T",F11="MAX"),IF(($E11*3*R11+Q11)<H11,"",($E11*3*R11+Q11)),""))) | AA11: =IF(Q11="","",IF(F11="Tolerance",IF(-(($E11*3*R11)-Q11)-G11>I11,"",-(($E11*3*R11)-Q11)-G11),IF(F11="MIN",IF(-(($E11*3*R11)-Q11)>I11,"",-(($E11*3*R11)-Q11)),""))) | AB11: =IF(OR(G11="",Q11=""),"",(L11+M11)/2-Q11) | AC11: =IF(OR($S11>$AC$9,$R11=""),"",$AC$9*6*$R11) | AE11: =IF(AD11="","",IF(AD11>=0.966,"Normal","Not Normal"))
A12: 2 | B12: 4-2-b | C12: D | D12: Height | E12: 1.5 | F12: Tolerance | G12: 0.5 | H12: 0.01 | I12: -0.01 | J12: OMM | K12: NO | L12: =IF(AND(G12="",H12=""),"",IF(G12="",H12,G12+H12)) -> 0.51 | M12: =IF(AND(G12="",I12=""),"",IF(G12="",I12,G12+I12)) -> 0.49 | O12: =IF(OR($AK12="",ISNUMBER($AK12)=FALSE),"",MAX(AK12:BP12)) | P12: =IF(OR($AK12="",ISNUMBER($AK12)=FALSE),"",MIN(AK12:BP12)) | Q12: =IF(OR($AK12="",ISNUMBER($AK12)=FALSE),"",AVERAGE(AK12:BP12)) | R12: =IF(OR($AK12="",ISNUMBER($AK12)=FALSE),"",STDEV(AK12:BP12)) | S12: =IF(OR($AK12="",ISNUMBER($AK12)=FALSE),"",IF(AND(G12="",I12=""),V12,IF(AND(G12="",H12=""),W12,(H12+ABS(I12))/(6*R12)))) | T12: =IF(OR($AK12="",ISNUMBER($AK12)=FALSE),"",IF(AND($F12="Tolerance",$G12<>""),($Q12-$G12)/(($L12-$M12)/2),IF(AND($F12="GD&T",$H12<>""),$Q12/$H12,""))) | U12: =IF($T12="","",IF(ABS($T12)<=0.125, "Level A",IF(AND(ABS($T12)>0.125,ABS($T12)<=0.25), "Level B",IF(AND(ABS($T12)>0.25,ABS($T12)<=0.5), "Level C", IF(ABS($T12)>0.5, "Level D"))))) | V12: =IF(OR($AK12="",ISNUMBER($AK12)=FALSE),"",IF(H12="","",(L12-Q12)/(3*R12))) | W12: =IF(OR($AK12="",ISNUMBER($AK12)=FALSE),"",IF(I12="","",(Q12-M12)/(3*R12))) | X12: =IF(OR($AK12="",ISNUMBER($AK12)=FALSE),"",IF(AND(G12=0,I12=0),((H12)-(Q12))/(3*R12),MIN(V12:W12))) | Y12: =IF(OR($AK12="",ISNUMBER($AK12)=FALSE),"",IF(AND(G12=0,I12=0),NORMSDIST(3*X12),NORMSDIST(3*X12)+NORMSDIST(6*S12-3*X12)-1)) | Z12: =IF($Q12="","",IF(F12="Tolerance",IF(($E12*3*R12+Q12)-G12<H12,"",($E12*3*R12+Q12)-G12),IF(OR(F12="GD&T",F12="MAX"),IF(($E12*3*R12+Q12)<H12,"",($E12*3*R12+Q12)),""))) | AA12: =IF(Q12="","",IF(F12="Tolerance",IF(-(($E12*3*R12)-Q12)-G12>I12,"",-(($E12*3*R12)-Q12)-G12),IF(F12="MIN",IF(-(($E12*3*R12)-Q12)>I12,"",-(($E12*3*R12)-Q12)),""))) | AB12: =IF(OR(G12="",Q12=""),"",(L12+M12)/2-Q12) | AC12: =IF(OR($S12>$AC$9,$R12=""),"",$AC$9*6*$R12) | AE12: =IF(AD12="","",IF(AD12>=0.966,"Normal","Not Normal"))
A13: 3 | B13: 4-3-c | C13: D | D13: Height | E13: 1.5 | F13: Tolerance | G13: 0.5 | H13: 0.01 | I13: -0.01 | J13: OMM | K13: NO | L13: =IF(AND(G13="",H13=""),"",IF(G13="",H13,G13+H13)) -> 0.51 | M13: =IF(AND(G13="",I13=""),"",IF(G13="",I13,G13+I13)) -> 0.49 | O13: =IF(OR($AK13="",ISNUMBER($AK13)=FALSE),"",MAX(AK13:BP13)) | P13: =IF(OR($AK13="",ISNUMBER($AK13)=FALSE),"",MIN(AK13:BP13)) | Q13: =IF(OR($AK13="",ISNUMBER($AK13)=FALSE),"",AVERAGE(AK13:BP13)) | R13: =IF(OR($AK13="",ISNUMBER($AK13)=FALSE),"",STDEV(AK13:BP13)) | S13: =IF(OR($AK13="",ISNUMBER($AK13)=FALSE),"",IF(AND(G13="",I13=""),V13,IF(AND(G13="",H13=""),W13,(H13+ABS(I13))/(6*R13)))) | T13: =IF(OR($AK13="",ISNUMBER($AK13)=FALSE),"",IF(AND($F13="Tolerance",$G13<>""),($Q13-$G13)/(($L13-$M13)/2),IF(AND($F13="GD&T",$H13<>""),$Q13/$H13,""))) | U13: =IF($T13="","",IF(ABS($T13)<=0.125, "Level A",IF(AND(ABS($T13)>0.125,ABS($T13)<=0.25), "Level B",IF(AND(ABS($T13)>0.25,ABS($T13)<=0.5), "Level C", IF(ABS($T13)>0.5, "Level D"))))) | V13: =IF(OR($AK13="",ISNUMBER($AK13)=FALSE),"",IF(H13="","",(L13-Q13)/(3*R13))) | W13: =IF(OR($AK13="",ISNUMBER($AK13)=FALSE),"",IF(I13="","",(Q13-M13)/(3*R13))) | X13: =IF(OR($AK13="",ISNUMBER($AK13)=FALSE),"",IF(AND(G13=0,I13=0),((H13)-(Q13))/(3*R13),MIN(V13:W13))) | Y13: =IF(OR($AK13="",ISNUMBER($AK13)=FALSE),"",IF(AND(G13=0,I13=0),NORMSDIST(3*X13),NORMSDIST(3*X13)+NORMSDIST(6*S13-3*X13)-1)) | Z13: =IF($Q13="","",IF(F13="Tolerance",IF(($E13*3*R13+Q13)-G13<H13,"",($E13*3*R13+Q13)-G13),IF(OR(F13="GD&T",F13="MAX"),IF(($E13*3*R13+Q13)<H13,"",($E13*3*R13+Q13)),""))) | AA13: =IF(Q13="","",IF(F13="Tolerance",IF(-(($E13*3*R13)-Q13)-G13>I13,"",-(($E13*3*R13)-Q13)-G13),IF(F13="MIN",IF(-(($E13*3*R13)-Q13)>I13,"",-(($E13*3*R13)-Q13)),""))) | AB13: =IF(OR(G13="",Q13=""),"",(L13+M13)/2-Q13) | AC13: =IF(OR($S13>$AC$9,$R13=""),"",$AC$9*6*$R13) | AE13: =IF(AD13="","",IF(AD13>=0.966,"Normal","Not Normal"))
A14: 4 | B14: 6-1-a | C14: F | D14: Height | E14: 1.5 | F14: Tolerance | G14: 0.5 | H14: 0.01 | I14: -0.01 | J14: OMM | K14: NO | L14: =IF(AND(G14="",H14=""),"",IF(G14="",H14,G14+H14)) -> 0.51 | M14: =IF(AND(G14="",I14=""),"",IF(G14="",I14,G14+I14)) -> 0.49 | O14: =IF(OR($AK14="",ISNUMBER($AK14)=FALSE),"",MAX(AK14:BP14)) | P14: =IF(OR($AK14="",ISNUMBER($AK14)=FALSE),"",MIN(AK14:BP14)) | Q14: =IF(OR($AK14="",ISNUMBER($AK14)=FALSE),"",AVERAGE(AK14:BP14)) | R14: =IF(OR($AK14="",ISNUMBER($AK14)=FALSE),"",STDEV(AK14:BP14)) | S14: =IF(OR($AK14="",ISNUMBER($AK14)=FALSE),"",IF(AND(G14="",I14=""),V14,IF(AND(G14="",H14=""),W14,(H14+ABS(I14))/(6*R14)))) | T14: =IF(OR($AK14="",ISNUMBER($AK14)=FALSE),"",IF(AND($F14="Tolerance",$G14<>""),($Q14-$G14)/(($L14-$M14)/2),IF(AND($F14="GD&T",$H14<>""),$Q14/$H14,""))) | U14: =IF($T14="","",IF(ABS($T14)<=0.125, "Level A",IF(AND(ABS($T14)>0.125,ABS($T14)<=0.25), "Level B",IF(AND(ABS($T14)>0.25,ABS($T14)<=0.5), "Level C", IF(ABS($T14)>0.5, "Level D"))))) | V14: =IF(OR($AK14="",ISNUMBER($AK14)=FALSE),"",IF(H14="","",(L14-Q14)/(3*R14))) | W14: =IF(OR($AK14="",ISNUMBER($AK14)=FALSE),"",IF(I14="","",(Q14-M14)/(3*R14))) | X14: =IF(OR($AK14="",ISNUMBER($AK14)=FALSE),"",IF(AND(G14=0,I14=0),((H14)-(Q14))/(3*R14),MIN(V14:W14))) | Y14: =IF(OR($AK14="",ISNUMBER($AK14)=FALSE),"",IF(AND(G14=0,I14=0),NORMSDIST(3*X14),NORMSDIST(3*X14)+NORMSDIST(6*S14-3*X14)-1)) | Z14: =IF($Q14="","",IF(F14="Tolerance",IF(($E14*3*R14+Q14)-G14<H14,"",($E14*3*R14+Q14)-G14),IF(OR(F14="GD&T",F14="MAX"),IF(($E14*3*R14+Q14)<H14,"",($E14*3*R14+Q14)),""))) | AA14: =IF(Q14="","",IF(F14="Tolerance",IF(-(($E14*3*R14)-Q14)-G14>I14,"",-(($E14*3*R14)-Q14)-G14),IF(F14="MIN",IF(-(($E14*3*R14)-Q14)>I14,"",-(($E14*3*R14)-Q14)),""))) | AB14: =IF(OR(G14="",Q14=""),"",(L14+M14)/2-Q14) | AC14: =IF(OR($S14>$AC$9,$R14=""),"",$AC$9*6*$R14) | AE14: =IF(AD14="","",IF(AD14>=0.966,"Normal","Not Normal"))
A15: 5 | B15: 6-2-b | C15: F | D15: Height | E15: 1.5 | F15: Tolerance | G15: 0.5 | H15: 0.01 | I15: -0.01 | J15: OMM | K15: NO | L15: =IF(AND(G15="",H15=""),"",IF(G15="",H15,G15+H15)) -> 0.51 | M15: =IF(AND(G15="",I15=""),"",IF(G15="",I15,G15+I15)) -> 0.49 | O15: =IF(OR($AK15="",ISNUMBER($AK15)=FALSE),"",MAX(AK15:BP15)) | P15: =IF(OR($AK15="",ISNUMBER($AK15)=FALSE),"",MIN(AK15:BP15)) | Q15: =IF(OR($AK15="",ISNUMBER($AK15)=FALSE),"",AVERAGE(AK15:BP15)) | R15: =IF(OR($AK15="",ISNUMBER($AK15)=FALSE),"",STDEV(AK15:BP15)) | S15: =IF(OR($AK15="",ISNUMBER($AK15)=FALSE),"",IF(AND(G15="",I15=""),V15,IF(AND(G15="",H15=""),W15,(H15+ABS(I15))/(6*R15)))) | T15: =IF(OR($AK15="",ISNUMBER($AK15)=FALSE),"",IF(AND($F15="Tolerance",$G15<>""),($Q15-$G15)/(($L15-$M15)/2),IF(AND($F15="GD&T",$H15<>""),$Q15/$H15,""))) | U15: =IF($T15="","",IF(ABS($T15)<=0.125, "Level A",IF(AND(ABS($T15)>0.125,ABS($T15)<=0.25), "Level B",IF(AND(ABS($T15)>0.25,ABS($T15)<=0.5), "Level C", IF(ABS($T15)>0.5, "Level D"))))) | V15: =IF(OR($AK15="",ISNUMBER($AK15)=FALSE),"",IF(H15="","",(L15-Q15)/(3*R15))) | W15: =IF(OR($AK15="",ISNUMBER($AK15)=FALSE),"",IF(I15="","",(Q15-M15)/(3*R15))) | X15: =IF(OR($AK15="",ISNUMBER($AK15)=FALSE),"",IF(AND(G15=0,I15=0),((H15)-(Q15))/(3*R15),MIN(V15:W15))) | Y15: =IF(OR($AK15="",ISNUMBER($AK15)=FALSE),"",IF(AND(G15=0,I15=0),NORMSDIST(3*X15),NORMSDIST(3*X15)+NORMSDIST(6*S15-3*X15)-1)) | Z15: =IF($Q15="","",IF(F15="Tolerance",IF(($E15*3*R15+Q15)-G15<H15,"",($E15*3*R15+Q15)-G15),IF(OR(F15="GD&T",F15="MAX"),IF(($E15*3*R15+Q15)<H15,"",($E15*3*R15+Q15)),""))) | AA15: =IF(Q15="","",IF(F15="Tolerance",IF(-(($E15*3*R15)-Q15)-G15>I15,"",-(($E15*3*R15)-Q15)-G15),IF(F15="MIN",IF(-(($E15*3*R15)-Q15)>I15,"",-(($E15*3*R15)-Q15)),""))) | AB15: =IF(OR(G15="",Q15=""),"",(L15+M15)/2-Q15) | AC15: =IF(OR($S15>$AC$9,$R15=""),"",$AC$9*6*$R15) | AE15: =IF(AD15="","",IF(AD15>=0.966,"Normal","Not Normal"))
A16: 6 | B16: 6-3-c | C16: F | D16: Height | E16: 1.5 | F16: Tolerance | G16: 0.5 | H16: 0.01 | I16: -0.01 | J16: OMM | K16: NO | L16: =IF(AND(G16="",H16=""),"",IF(G16="",H16,G16+H16)) -> 0.51 | M16: =IF(AND(G16="",I16=""),"",IF(G16="",I16,G16+I16)) -> 0.49 | O16: =IF(OR($AK16="",ISNUMBER($AK16)=FALSE),"",MAX(AK16:BP16)) | P16: =IF(OR($AK16="",ISNUMBER($AK16)=FALSE),"",MIN(AK16:BP16)) | Q16: =IF(OR($AK16="",ISNUMBER($AK16)=FALSE),"",AVERAGE(AK16:BP16)) | R16: =IF(OR($AK16="",ISNUMBER($AK16)=FALSE),"",STDEV(AK16:BP16)) | S16: =IF(OR($AK16="",ISNUMBER($AK16)=FALSE),"",IF(AND(G16="",I16=""),V16,IF(AND(G16="",H16=""),W16,(H16+ABS(I16))/(6*R16)))) | T16: =IF(OR($AK16="",ISNUMBER($AK16)=FALSE),"",IF(AND($F16="Tolerance",$G16<>""),($Q16-$G16)/(($L16-$M16)/2),IF(AND($F16="GD&T",$H16<>""),$Q16/$H16,""))) | U16: =IF($T16="","",IF(ABS($T16)<=0.125, "Level A",IF(AND(ABS($T16)>0.125,ABS($T16)<=0.25), "Level B",IF(AND(ABS($T16)>0.25,ABS($T16)<=0.5), "Level C", IF(ABS($T16)>0.5, "Level D"))))) | V16: =IF(OR($AK16="",ISNUMBER($AK16)=FALSE),"",IF(H16="","",(L16-Q16)/(3*R16))) | W16: =IF(OR($AK16="",ISNUMBER($AK16)=FALSE),"",IF(I16="","",(Q16-M16)/(3*R16))) | X16: =IF(OR($AK16="",ISNUMBER($AK16)=FALSE),"",IF(AND(G16=0,I16=0),((H16)-(Q16))/(3*R16),MIN(V16:W16))) | Y16: =IF(OR($AK16="",ISNUMBER($AK16)=FALSE),"",IF(AND(G16=0,I16=0),NORMSDIST(3*X16),NORMSDIST(3*X16)+NORMSDIST(6*S16-3*X16)-1)) | Z16: =IF($Q16="","",IF(F16="Tolerance",IF(($E16*3*R16+Q16)-G16<H16,"",($E16*3*R16+Q16)-G16),IF(OR(F16="GD&T",F16="MAX"),IF(($E16*3*R16+Q16)<H16,"",($E16*3*R16+Q16)),""))) | AA16: =IF(Q16="","",IF(F16="Tolerance",IF(-(($E16*3*R16)-Q16)-G16>I16,"",-(($E16*3*R16)-Q16)-G16),IF(F16="MIN",IF(-(($E16*3*R16)-Q16)>I16,"",-(($E16*3*R16)-Q16)),""))) | AB16: =IF(OR(G16="",Q16=""),"",(L16+M16)/2-Q16) | AC16: =IF(OR($S16>$AC$9,$R16=""),"",$AC$9*6*$R16) | AE16: =IF(AD16="","",IF(AD16>=0.966,"Normal","Not Normal"))
A17: 7 | B17: 8 | C17: H | D17: Parallelism | E17: 1.5 | F17: GD&T | H17: 0.03 | J17: OMM | K17: NO | L17: =IF(AND(G17="",H17=""),"",IF(G17="",H17,G17+H17)) -> 0.03 | M17: =IF(AND(G17="",I17=""),"",IF(G17="",I17,G17+I17)) | O17: =IF(OR($AK17="",ISNUMBER($AK17)=FALSE),"",MAX(AK17:BP17)) | P17: =IF(OR($AK17="",ISNUMBER($AK17)=FALSE),"",MIN(AK17:BP17)) | Q17: =IF(OR($AK17="",ISNUMBER($AK17)=FALSE),"",AVERAGE(AK17:BP17)) | R17: =IF(OR($AK17="",ISNUMBER($AK17)=FALSE),"",STDEV(AK17:BP17)) | S17: =IF(OR($AK17="",ISNUMBER($AK17)=FALSE),"",IF(AND(G17="",I17=""),V17,IF(AND(G17="",H17=""),W17,(H17+ABS(I17))/(6*R17)))) | T17: =IF(OR($AK17="",ISNUMBER($AK17)=FALSE),"",IF(AND($F17="Tolerance",$G17<>""),($Q17-$G17)/(($L17-$M17)/2),IF(AND($F17="GD&T",$H17<>""),$Q17/$H17,""))) | U17: =IF($T17="","",IF(ABS($T17)<=0.125, "Level A",IF(AND(ABS($T17)>0.125,ABS($T17)<=0.25), "Level B",IF(AND(ABS($T17)>0.25,ABS($T17)<=0.5), "Level C", IF(ABS($T17)>0.5, "Level D"))))) | V17: =IF(OR($AK17="",ISNUMBER($AK17)=FALSE),"",IF(H17="","",(L17-Q17)/(3*R17))) | W17: =IF(OR($AK17="",ISNUMBER($AK17)=FALSE),"",IF(I17="","",(Q17-M17)/(3*R17))) | X17: =IF(OR($AK17="",ISNUMBER($AK17)=FALSE),"",IF(AND(G17=0,I17=0),((H17)-(Q17))/(3*R17),MIN(V17:W17))) | Y17: =IF(OR($AK17="",ISNUMBER($AK17)=FALSE),"",IF(AND(G17=0,I17=0),NORMSDIST(3*X17),NORMSDIST(3*X17)+NORMSDIST(6*S17-3*X17)-1)) | Z17: =IF($Q17="","",IF(F17="Tolerance",IF(($E17*3*R17+Q17)-G17<H17,"",($E17*3*R17+Q17)-G17),IF(OR(F17="GD&T",F17="MAX"),IF(($E17*3*R17+Q17)<H17,"",($E17*3*R17+Q17)),""))) | AA17: =IF(Q17="","",IF(F17="Tolerance",IF(-(($E17*3*R17)-Q17)-G17>I17,"",-(($E17*3*R17)-Q17)-G17),IF(F17="MIN",IF(-(($E17*3*R17)-Q17)>I17,"",-(($E17*3*R17)-Q17)),""))) | AB17: =IF(OR(G17="",Q17=""),"",(L17+M17)/2-Q17) | AC17: =IF(OR($S17>$AC$9,$R17=""),"",$AC$9*6*$R17) | AE17: =IF(AD17="","",IF(AD17>=0.966,"Normal","Not Normal"))
A18: 11 | B18: 9 | C18: I | D18: Perpendicularity | E18: 1.5 | F18: GD&T | H18: 0.03 | J18: OMM | K18: NO | L18: =IF(AND(G18="",H18=""),"",IF(G18="",H18,G18+H18)) -> 0.03 | M18: =IF(AND(G18="",I18=""),"",IF(G18="",I18,G18+I18)) | O18: =IF(OR($AK18="",ISNUMBER($AK18)=FALSE),"",MAX(AK18:BP18)) | P18: =IF(OR($AK18="",ISNUMBER($AK18)=FALSE),"",MIN(AK18:BP18)) | Q18: =IF(OR($AK18="",ISNUMBER($AK18)=FALSE),"",AVERAGE(AK18:BP18)) | R18: =IF(OR($AK18="",ISNUMBER($AK18)=FALSE),"",STDEV(AK18:BP18)) | S18: =IF(OR($AK18="",ISNUMBER($AK18)=FALSE),"",IF(AND(G18="",I18=""),V18,IF(AND(G18="",H18=""),W18,(H18+ABS(I18))/(6*R18)))) | T18: =IF(OR($AK18="",ISNUMBER($AK18)=FALSE),"",IF(AND($F18="Tolerance",$G18<>""),($Q18-$G18)/(($L18-$M18)/2),IF(AND($F18="GD&T",$H18<>""),$Q18/$H18,""))) | U18: =IF($T18="","",IF(ABS($T18)<=0.125, "Level A",IF(AND(ABS($T18)>0.125,ABS($T18)<=0.25), "Level B",IF(AND(ABS($T18)>0.25,ABS($T18)<=0.5), "Level C", IF(ABS($T18)>0.5, "Level D"))))) | V18: =IF(OR($AK18="",ISNUMBER($AK18)=FALSE),"",IF(H18="","",(L18-Q18)/(3*R18))) | W18: =IF(OR($AK18="",ISNUMBER($AK18)=FALSE),"",IF(I18="","",(Q18-M18)/(3*R18))) | X18: =IF(OR($AK18="",ISNUMBER($AK18)=FALSE),"",IF(AND(G18=0,I18=0),((H18)-(Q18))/(3*R18),MIN(V18:W18))) | Y18: =IF(OR($AK18="",ISNUMBER($AK18)=FALSE),"",IF(AND(G18=0,I18=0),NORMSDIST(3*X18),NORMSDIST(3*X18)+NORMSDIST(6*S18-3*X18)-1)) | Z18: =IF($Q18="","",IF(F18="Tolerance",IF(($E18*3*R18+Q18)-G18<H18,"",($E18*3*R18+Q18)-G18),IF(OR(F18="GD&T",F18="MAX"),IF(($E18*3*R18+Q18)<H18,"",($E18*3*R18+Q18)),""))) | AA18: =IF(Q18="","",IF(F18="Tolerance",IF(-(($E18*3*R18)-Q18)-G18>I18,"",-(($E18*3*R18)-Q18)-G18),IF(F18="MIN",IF(-(($E18*3*R18)-Q18)>I18,"",-(($E18*3*R18)-Q18)),""))) | AB18: =IF(OR(G18="",Q18=""),"",(L18+M18)/2-Q18) | AC18: =IF(OR($S18>$AC$9,$R18=""),"",$AC$9*6*$R18) | AE18: =IF(AD18="","",IF(AD18>=0.966,"Normal","Not Normal"))
A19: 12 | B19: 10-1-d | C19: J | D19: Distance | E19: 1.33 | F19: Tolerance | G19: 1.09 | H19: 0.015 | I19: -0.01 | J19: OMM | K19: NO | L19: =IF(AND(G19="",H19=""),"",IF(G19="",H19,G19+H19)) -> 1.105 | M19: =IF(AND(G19="",I19=""),"",IF(G19="",I19,G19+I19)) -> 1.08 | O19: =IF(OR($AK19="",ISNUMBER($AK19)=FALSE),"",MAX(AK19:BP19)) | P19: =IF(OR($AK19="",ISNUMBER($AK19)=FALSE),"",MIN(AK19:BP19)) | Q19: =IF(OR($AK19="",ISNUMBER($AK19)=FALSE),"",AVERAGE(AK19:BP19)) | R19: =IF(OR($AK19="",ISNUMBER($AK19)=FALSE),"",STDEV(AK19:BP19)) | S19: =IF(OR($AK19="",ISNUMBER($AK19)=FALSE),"",IF(AND(G19="",I19=""),V19,IF(AND(G19="",H19=""),W19,(H19+ABS(I19))/(6*R19)))) | T19: =IF(OR($AK19="",ISNUMBER($AK19)=FALSE),"",IF(AND($F19="Tolerance",$G19<>""),($Q19-$G19)/(($L19-$M19)/2),IF(AND($F19="GD&T",$H19<>""),$Q19/$H19,""))) | U19: =IF($T19="","",IF(ABS($T19)<=0.125, "Level A",IF(AND(ABS($T19)>0.125,ABS($T19)<=0.25), "Level B",IF(AND(ABS($T19)>0.25,ABS($T19)<=0.5), "Level C", IF(ABS($T19)>0.5, "Level D"))))) | V19: =IF(OR($AK19="",ISNUMBER($AK19)=FALSE),"",IF(H19="","",(L19-Q19)/(3*R19))) | W19: =IF(OR($AK19="",ISNUMBER($AK19)=FALSE),"",IF(I19="","",(Q19-M19)/(3*R19))) | X19: =IF(OR($AK19="",ISNUMBER($AK19)=FALSE),"",IF(AND(G19=0,I19=0),((H19)-(Q19))/(3*R19),MIN(V19:W19))) | Y19: =IF(OR($AK19="",ISNUMBER($AK19)=FALSE),"",IF(AND(G19=0,I19=0),NORMSDIST(3*X19),NORMSDIST(3*X19)+NORMSDIST(6*S19-3*X19)-1)) | Z19: =IF($Q19="","",IF(F19="Tolerance",IF(($E19*3*R19+Q19)-G19<H19,"",($E19*3*R19+Q19)-G19),IF(OR(F19="GD&T",F19="MAX"),IF(($E19*3*R19+Q19)<H19,"",($E19*3*R19+Q19)),""))) | AA19: =IF(Q19="","",IF(F19="Tolerance",IF(-(($E19*3*R19)-Q19)-G19>I19,"",-(($E19*3*R19)-Q19)-G19),IF(F19="MIN",IF(-(($E19*3*R19)-Q19)>I19,"",-(($E19*3*R19)-Q19)),""))) | AB19: =IF(OR(G19="",Q19=""),"",(L19+M19)/2-Q19) | AC19: =IF(OR($S19>$AC$9,$R19=""),"",$AC$9*6*$R19) | AE19: =IF(AD19="","",IF(AD19>=0.966,"Normal","Not Normal"))
A20: 13 | B20: 10-2-e | C20: J | D20: Distance | E20: 1.33 | F20: Tolerance | G20: 1.09 | H20: 0.015 | I20: -0.01 | J20: OMM | K20: NO | L20: =IF(AND(G20="",H20=""),"",IF(G20="",H20,G20+H20)) -> 1.105 | M20: =IF(AND(G20="",I20=""),"",IF(G20="",I20,G20+I20)) -> 1.08 | O20: =IF(OR($AK20="",ISNUMBER($AK20)=FALSE),"",MAX(AK20:BP20)) | P20: =IF(OR($AK20="",ISNUMBER($AK20)=FALSE),"",MIN(AK20:BP20)) | Q20: =IF(OR($AK20="",ISNUMBER($AK20)=FALSE),"",AVERAGE(AK20:BP20)) | R20: =IF(OR($AK20="",ISNUMBER($AK20)=FALSE),"",STDEV(AK20:BP20)) | S20: =IF(OR($AK20="",ISNUMBER($AK20)=FALSE),"",IF(AND(G20="",I20=""),V20,IF(AND(G20="",H20=""),W20,(H20+ABS(I20))/(6*R20)))) | T20: =IF(OR($AK20="",ISNUMBER($AK20)=FALSE),"",IF(AND($F20="Tolerance",$G20<>""),($Q20-$G20)/(($L20-$M20)/2),IF(AND($F20="GD&T",$H20<>""),$Q20/$H20,""))) | U20: =IF($T20="","",IF(ABS($T20)<=0.125, "Level A",IF(AND(ABS($T20)>0.125,ABS($T20)<=0.25), "Level B",IF(AND(ABS($T20)>0.25,ABS($T20)<=0.5), "Level C", IF(ABS($T20)>0.5, "Level D"))))) | V20: =IF(OR($AK20="",ISNUMBER($AK20)=FALSE),"",IF(H20="","",(L20-Q20)/(3*R20))) | W20: =IF(OR($AK20="",ISNUMBER($AK20)=FALSE),"",IF(I20="","",(Q20-M20)/(3*R20))) | X20: =IF(OR($AK20="",ISNUMBER($AK20)=FALSE),"",IF(AND(G20=0,I20=0),((H20)-(Q20))/(3*R20),MIN(V20:W20))) | Y20: =IF(OR($AK20="",ISNUMBER($AK20)=FALSE),"",IF(AND(G20=0,I20=0),NORMSDIST(3*X20),NORMSDIST(3*X20)+NORMSDIST(6*S20-3*X20)-1)) | Z20: =IF($Q20="","",IF(F20="Tolerance",IF(($E20*3*R20+Q20)-G20<H20,"",($E20*3*R20+Q20)-G20),IF(OR(F20="GD&T",F20="MAX"),IF(($E20*3*R20+Q20)<H20,"",($E20*3*R20+Q20)),""))) | AA20: =IF(Q20="","",IF(F20="Tolerance",IF(-(($E20*3*R20)-Q20)-G20>I20,"",-(($E20*3*R20)-Q20)-G20),IF(F20="MIN",IF(-(($E20*3*R20)-Q20)>I20,"",-(($E20*3*R20)-Q20)),""))) | AB20: =IF(OR(G20="",Q20=""),"",(L20+M20)/2-Q20) | AC20: =IF(OR($S20>$AC$9,$R20=""),"",$AC$9*6*$R20) | AE20: =IF(AD20="","",IF(AD20>=0.966,"Normal","Not Normal"))
A21: 14 | B21: 10-3-f | C21: J | D21: Distance | E21: 1.33 | F21: Tolerance | G21: 1.09 | H21: 0.015 | I21: -0.01 | J21: OMM | K21: NO | L21: =IF(AND(G21="",H21=""),"",IF(G21="",H21,G21+H21)) -> 1.105 | M21: =IF(AND(G21="",I21=""),"",IF(G21="",I21,G21+I21)) -> 1.08 | O21: =IF(OR($AK21="",ISNUMBER($AK21)=FALSE),"",MAX(AK21:BP21)) | P21: =IF(OR($AK21="",ISNUMBER($AK21)=FALSE),"",MIN(AK21:BP21)) | Q21: =IF(OR($AK21="",ISNUMBER($AK21)=FALSE),"",AVERAGE(AK21:BP21)) | R21: =IF(OR($AK21="",ISNUMBER($AK21)=FALSE),"",STDEV(AK21:BP21)) | S21: =IF(OR($AK21="",ISNUMBER($AK21)=FALSE),"",IF(AND(G21="",I21=""),V21,IF(AND(G21="",H21=""),W21,(H21+ABS(I21))/(6*R21)))) | T21: =IF(OR($AK21="",ISNUMBER($AK21)=FALSE),"",IF(AND($F21="Tolerance",$G21<>""),($Q21-$G21)/(($L21-$M21)/2),IF(AND($F21="GD&T",$H21<>""),$Q21/$H21,""))) | U21: =IF($T21="","",IF(ABS($T21)<=0.125, "Level A",IF(AND(ABS($T21)>0.125,ABS($T21)<=0.25), "Level B",IF(AND(ABS($T21)>0.25,ABS($T21)<=0.5), "Level C", IF(ABS($T21)>0.5, "Level D"))))) | V21: =IF(OR($AK21="",ISNUMBER($AK21)=FALSE),"",IF(H21="","",(L21-Q21)/(3*R21))) | W21: =IF(OR($AK21="",ISNUMBER($AK21)=FALSE),"",IF(I21="","",(Q21-M21)/(3*R21))) | X21: =IF(OR($AK21="",ISNUMBER($AK21)=FALSE),"",IF(AND(G21=0,I21=0),((H21)-(Q21))/(3*R21),MIN(V21:W21))) | Y21: =IF(OR($AK21="",ISNUMBER($AK21)=FALSE),"",IF(AND(G21=0,I21=0),NORMSDIST(3*X21),NORMSDIST(3*X21)+NORMSDIST(6*S21-3*X21)-1)) | Z21: =IF($Q21="","",IF(F21="Tolerance",IF(($E21*3*R21+Q21)-G21<H21,"",($E21*3*R21+Q21)-G21),IF(OR(F21="GD&T",F21="MAX"),IF(($E21*3*R21+Q21)<H21,"",($E21*3*R21+Q21)),""))) | AA21: =IF(Q21="","",IF(F21="Tolerance",IF(-(($E21*3*R21)-Q21)-G21>I21,"",-(($E21*3*R21)-Q21)-G21),IF(F21="MIN",IF(-(($E21*3*R21)-Q21)>I21,"",-(($E21*3*R21)-Q21)),""))) | AB21: =IF(OR(G21="",Q21=""),"",(L21+M21)/2-Q21) | AC21: =IF(OR($S21>$AC$9,$R21=""),"",$AC$9*6*$R21) | AE21: =IF(AD21="","",IF(AD21>=0.966,"Normal","Not Normal"))
A22: 15 | B22: 23 | C22: W | D22: Distance | E22: 1.33 | F22: Tolerance | G22: 1.852 | H22: 0.02 | I22: -0.02 | J22: OMM | K22: NO | L22: =IF(AND(G22="",H22=""),"",IF(G22="",H22,G22+H22)) -> 1.872 | M22: =IF(AND(G22="",I22=""),"",IF(G22="",I22,G22+I22)) -> 1.832 | O22: =IF(OR($AK22="",ISNUMBER($AK22)=FALSE),"",MAX(AK22:BP22)) | P22: =IF(OR($AK22="",ISNUMBER($AK22)=FALSE),"",MIN(AK22:BP22)) | Q22: =IF(OR($AK22="",ISNUMBER($AK22)=FALSE),"",AVERAGE(AK22:BP22)) | R22: =IF(OR($AK22="",ISNUMBER($AK22)=FALSE),"",STDEV(AK22:BP22)) | S22: =IF(OR($AK22="",ISNUMBER($AK22)=FALSE),"",IF(AND(G22="",I22=""),V22,IF(AND(G22="",H22=""),W22,(H22+ABS(I22))/(6*R22)))) | T22: =IF(OR($AK22="",ISNUMBER($AK22)=FALSE),"",IF(AND($F22="Tolerance",$G22<>""),($Q22-$G22)/(($L22-$M22)/2),IF(AND($F22="GD&T",$H22<>""),$Q22/$H22,""))) | U22: =IF($T22="","",IF(ABS($T22)<=0.125, "Level A",IF(AND(ABS($T22)>0.125,ABS($T22)<=0.25), "Level B",IF(AND(ABS($T22)>0.25,ABS($T22)<=0.5), "Level C", IF(ABS($T22)>0.5, "Level D"))))) | V22: =IF(OR($AK22="",ISNUMBER($AK22)=FALSE),"",IF(H22="","",(L22-Q22)/(3*R22))) | W22: =IF(OR($AK22="",ISNUMBER($AK22)=FALSE),"",IF(I22="","",(Q22-M22)/(3*R22))) | X22: =IF(OR($AK22="",ISNUMBER($AK22)=FALSE),"",IF(AND(G22=0,I22=0),((H22)-(Q22))/(3*R22),MIN(V22:W22))) | Y22: =IF(OR($AK22="",ISNUMBER($AK22)=FALSE),"",IF(AND(G22=0,I22=0),NORMSDIST(3*X22),NORMSDIST(3*X22)+NORMSDIST(6*S22-3*X22)-1)) | Z22: =IF($Q22="","",IF(F22="Tolerance",IF(($E22*3*R22+Q22)-G22<H22,"",($E22*3*R22+Q22)-G22),IF(OR(F22="GD&T",F22="MAX"),IF(($E22*3*R22+Q22)<H22,"",($E22*3*R22+Q22)),""))) | AA22: =IF(Q22="","",IF(F22="Tolerance",IF(-(($E22*3*R22)-Q22)-G22>I22,"",-(($E22*3*R22)-Q22)-G22),IF(F22="MIN",IF(-(($E22*3*R22)-Q22)>I22,"",-(($E22*3*R22)-Q22)),""))) | AB22: =IF(OR(G22="",Q22=""),"",(L22+M22)/2-Q22) | AC22: =IF(OR($S22>$AC$9,$R22=""),"",$AC$9*6*$R22) | AE22: =IF(AD22="","",IF(AD22>=0.966,"Normal","Not Normal"))
A23: 15 | B23: 24 | C23: X | D23: Distance | E23: 1.33 | F23: Tolerance | G23: 0.214 | H23: 0.02 | I23: -0.02 | J23: OMM | K23: NO | L23: =IF(AND(G23="",H23=""),"",IF(G23="",H23,G23+H23)) -> 0.234 | M23: =IF(AND(G23="",I23=""),"",IF(G23="",I23,G23+I23)) -> 0.194 | O23: =IF(OR($AK23="",ISNUMBER($AK23)=FALSE),"",MAX(AK23:BP23)) | P23: =IF(OR($AK23="",ISNUMBER($AK23)=FALSE),"",MIN(AK23:BP23)) | Q23: =IF(OR($AK23="",ISNUMBER($AK23)=FALSE),"",AVERAGE(AK23:BP23)) | R23: =IF(OR($AK23="",ISNUMBER($AK23)=FALSE),"",STDEV(AK23:BP23)) | S23: =IF(OR($AK23="",ISNUMBER($AK23)=FALSE),"",IF(AND(G23="",I23=""),V23,IF(AND(G23="",H23=""),W23,(H23+ABS(I23))/(6*R23)))) | T23: =IF(OR($AK23="",ISNUMBER($AK23)=FALSE),"",IF(AND($F23="Tolerance",$G23<>""),($Q23-$G23)/(($L23-$M23)/2),IF(AND($F23="GD&T",$H23<>""),$Q23/$H23,""))) | U23: =IF($T23="","",IF(ABS($T23)<=0.125, "Level A",IF(AND(ABS($T23)>0.125,ABS($T23)<=0.25), "Level B",IF(AND(ABS($T23)>0.25,ABS($T23)<=0.5), "Level C", IF(ABS($T23)>0.5, "Level D"))))) | V23: =IF(OR($AK23="",ISNUMBER($AK23)=FALSE),"",IF(H23="","",(L23-Q23)/(3*R23))) | W23: =IF(OR($AK23="",ISNUMBER($AK23)=FALSE),"",IF(I23="","",(Q23-M23)/(3*R23))) | X23: =IF(OR($AK23="",ISNUMBER($AK23)=FALSE),"",IF(AND(G23=0,I23=0),((H23)-(Q23))/(3*R23),MIN(V23:W23))) | Y23: =IF(OR($AK23="",ISNUMBER($AK23)=FALSE),"",IF(AND(G23=0,I23=0),NORMSDIST(3*X23),NORMSDIST(3*X23)+NORMSDIST(6*S23-3*X23)-1)) | Z23: =IF($Q23="","",IF(F23="Tolerance",IF(($E23*3*R23+Q23)-G23<H23,"",($E23*3*R23+Q23)-G23),IF(OR(F23="GD&T",F23="MAX"),IF(($E23*3*R23+Q23)<H23,"",($E23*3*R23+Q23)),""))) | AA23: =IF(Q23="","",IF(F23="Tolerance",IF(-(($E23*3*R23)-Q23)-G23>I23,"",-(($E23*3*R23)-Q23)-G23),IF(F23="MIN",IF(-(($E23*3*R23)-Q23)>I23,"",-(($E23*3*R23)-Q23)),""))) | AB23: =IF(OR(G23="",Q23=""),"",(L23+M23)/2-Q23) | AC23: =IF(OR($S23>$AC$9,$R23=""),"",$AC$9*6*$R23) | AE23: =IF(AD23="","",IF(AD23>=0.966,"Normal","Not Normal"))
A24: 17 | B24: 25A-d | D24: Distance | F24: Tolerance | G24: 1.29 | H24: 0.03 | I24: -0.03 | J24: OMM | K24: NO | L24: =IF(AND(G24="",H24=""),"",IF(G24="",H24,G24+H24)) -> 1.32 | M24: =IF(AND(G24="",I24=""),"",IF(G24="",I24,G24+I24)) -> 1.26 | O24: =IF(OR($AK24="",ISNUMBER($AK24)=FALSE),"",MAX(AK24:BP24)) | P24: =IF(OR($AK24="",ISNUMBER($AK24)=FALSE),"",MIN(AK24:BP24)) | Q24: =IF(OR($AK24="",ISNUMBER($AK24)=FALSE),"",AVERAGE(AK24:BP24)) | R24: =IF(OR($AK24="",ISNUMBER($AK24)=FALSE),"",STDEV(AK24:BP24)) | S24: =IF(OR($AK24="",ISNUMBER($AK24)=FALSE),"",IF(AND(G24="",I24=""),V24,IF(AND(G24="",H24=""),W24,(H24+ABS(I24))/(6*R24)))) | T24: =IF(OR($AK24="",ISNUMBER($AK24)=FALSE),"",IF(AND($F24="Tolerance",$G24<>""),($Q24-$G24)/(($L24-$M24)/2),IF(AND($F24="GD&T",$H24<>""),$Q24/$H24,""))) | U24: =IF($T24="","",IF(ABS($T24)<=0.125, "Level A",IF(AND(ABS($T24)>0.125,ABS($T24)<=0.25), "Level B",IF(AND(ABS($T24)>0.25,ABS($T24)<=0.5), "Level C", IF(ABS($T24)>0.5, "Level D"))))) | V24: =IF(OR($AK24="",ISNUMBER($AK24)=FALSE),"",IF(H24="","",(L24-Q24)/(3*R24))) | W24: =IF(OR($AK24="",ISNUMBER($AK24)=FALSE),"",IF(I24="","",(Q24-M24)/(3*R24))) | X24: =IF(OR($AK24="",ISNUMBER($AK24)=FALSE),"",IF(AND(G24=0,I24=0),((H24)-(Q24))/(3*R24),MIN(V24:W24))) | Y24: =IF(OR($AK24="",ISNUMBER($AK24)=FALSE),"",IF(AND(G24=0,I24=0),NORMSDIST(3*X24),NORMSDIST(3*X24)+NORMSDIST(6*S24-3*X24)-1)) | Z24: =IF($Q24="","",IF(F24="Tolerance",IF(($E24*3*R24+Q24)-G24<H24,"",($E24*3*R24+Q24)-G24),IF(OR(F24="GD&T",F24="MAX"),IF(($E24*3*R24+Q24)<H24,"",($E24*3*R24+Q24)),""))) | AA24: =IF(Q24="","",IF(F24="Tolerance",IF(-(($E24*3*R24)-Q24)-G24>I24,"",-(($E24*3*R24)-Q24)-G24),IF(F24="MIN",IF(-(($E24*3*R24)-Q24)>I24,"",-(($E24*3*R24)-Q24)),""))) | AB24: =IF(OR(G24="",Q24=""),"",(L24+M24)/2-Q24) | AC24: =IF(OR($S24>$AC$9,$R24=""),"",$AC$9*6*$R24) | AE24: =IF(AD24="","",IF(AD24>=0.966,"Normal","Not Normal"))
A25: 18 | B25: 25A-e | D25: Distance | F25: Tolerance | G25: 1.29 | H25: 0.03 | I25: -0.03 | J25: OMM | K25: NO | L25: =IF(AND(G25="",H25=""),"",IF(G25="",H25,G25+H25)) -> 1.32 | M25: =IF(AND(G25="",I25=""),"",IF(G25="",I25,G25+I25)) -> 1.26 | O25: =IF(OR($AK25="",ISNUMBER($AK25)=FALSE),"",MAX(AK25:BP25)) | P25: =IF(OR($AK25="",ISNUMBER($AK25)=FALSE),"",MIN(AK25:BP25)) | Q25: =IF(OR($AK25="",ISNUMBER($AK25)=FALSE),"",AVERAGE(AK25:BP25)) | R25: =IF(OR($AK25="",ISNUMBER($AK25)=FALSE),"",STDEV(AK25:BP25)) | S25: =IF(OR($AK25="",ISNUMBER($AK25)=FALSE),"",IF(AND(G25="",I25=""),V25,IF(AND(G25="",H25=""),W25,(H25+ABS(I25))/(6*R25)))) | T25: =IF(OR($AK25="",ISNUMBER($AK25)=FALSE),"",IF(AND($F25="Tolerance",$G25<>""),($Q25-$G25)/(($L25-$M25)/2),IF(AND($F25="GD&T",$H25<>""),$Q25/$H25,""))) | U25: =IF($T25="","",IF(ABS($T25)<=0.125, "Level A",IF(AND(ABS($T25)>0.125,ABS($T25)<=0.25), "Level B",IF(AND(ABS($T25)>0.25,ABS($T25)<=0.5), "Level C", IF(ABS($T25)>0.5, "Level D"))))) | V25: =IF(OR($AK25="",ISNUMBER($AK25)=FALSE),"",IF(H25="","",(L25-Q25)/(3*R25))) | W25: =IF(OR($AK25="",ISNUMBER($AK25)=FALSE),"",IF(I25="","",(Q25-M25)/(3*R25))) | X25: =IF(OR($AK25="",ISNUMBER($AK25)=FALSE),"",IF(AND(G25=0,I25=0),((H25)-(Q25))/(3*R25),MIN(V25:W25))) | Y25: =IF(OR($AK25="",ISNUMBER($AK25)=FALSE),"",IF(AND(G25=0,I25=0),NORMSDIST(3*X25),NORMSDIST(3*X25)+NORMSDIST(6*S25-3*X25)-1)) | Z25: =IF($Q25="","",IF(F25="Tolerance",IF(($E25*3*R25+Q25)-G25<H25,"",($E25*3*R25+Q25)-G25),IF(OR(F25="GD&T",F25="MAX"),IF(($E25*3*R25+Q25)<H25,"",($E25*3*R25+Q25)),""))) | AA25: =IF(Q25="","",IF(F25="Tolerance",IF(-(($E25*3*R25)-Q25)-G25>I25,"",-(($E25*3*R25)-Q25)-G25),IF(F25="MIN",IF(-(($E25*3*R25)-Q25)>I25,"",-(($E25*3*R25)-Q25)),""))) | AB25: =IF(OR(G25="",Q25=""),"",(L25+M25)/2-Q25) | AC25: =IF(OR($S25>$AC$9,$R25=""),"",$AC$9*6*$R25) | AE25: =IF(AD25="","",IF(AD25>=0.966,"Normal","Not Normal"))
A26: 19 | B26: 25A-f | D26: Distance | F26: Tolerance | G26: 1.29 | H26: 0.03 | I26: -0.03 | J26: OMM | K26: NO | L26: =IF(AND(G26="",H26=""),"",IF(G26="",H26,G26+H26)) -> 1.32 | M26: =IF(AND(G26="",I26=""),"",IF(G26="",I26,G26+I26)) -> 1.26 | O26: =IF(OR($AK26="",ISNUMBER($AK26)=FALSE),"",MAX(AK26:BP26)) | P26: =IF(OR($AK26="",ISNUMBER($AK26)=FALSE),"",MIN(AK26:BP26)) | Q26: =IF(OR($AK26="",ISNUMBER($AK26)=FALSE),"",AVERAGE(AK26:BP26)) | R26: =IF(OR($AK26="",ISNUMBER($AK26)=FALSE),"",STDEV(AK26:BP26)) | S26: =IF(OR($AK26="",ISNUMBER($AK26)=FALSE),"",IF(AND(G26="",I26=""),V26,IF(AND(G26="",H26=""),W26,(H26+ABS(I26))/(6*R26)))) | T26: =IF(OR($AK26="",ISNUMBER($AK26)=FALSE),"",IF(AND($F26="Tolerance",$G26<>""),($Q26-$G26)/(($L26-$M26)/2),IF(AND($F26="GD&T",$H26<>""),$Q26/$H26,""))) | U26: =IF($T26="","",IF(ABS($T26)<=0.125, "Level A",IF(AND(ABS($T26)>0.125,ABS($T26)<=0.25), "Level B",IF(AND(ABS($T26)>0.25,ABS($T26)<=0.5), "Level C", IF(ABS($T26)>0.5, "Level D"))))) | V26: =IF(OR($AK26="",ISNUMBER($AK26)=FALSE),"",IF(H26="","",(L26-Q26)/(3*R26))) | W26: =IF(OR($AK26="",ISNUMBER($AK26)=FALSE),"",IF(I26="","",(Q26-M26)/(3*R26))) | X26: =IF(OR($AK26="",ISNUMBER($AK26)=FALSE),"",IF(AND(G26=0,I26=0),((H26)-(Q26))/(3*R26),MIN(V26:W26))) | Y26: =IF(OR($AK26="",ISNUMBER($AK26)=FALSE),"",IF(AND(G26=0,I26=0),NORMSDIST(3*X26),NORMSDIST(3*X26)+NORMSDIST(6*S26-3*X26)-1)) | Z26: =IF($Q26="","",IF(F26="Tolerance",IF(($E26*3*R26+Q26)-G26<H26,"",($E26*3*R26+Q26)-G26),IF(OR(F26="GD&T",F26="MAX"),IF(($E26*3*R26+Q26)<H26,"",($E26*3*R26+Q26)),""))) | AA26: =IF(Q26="","",IF(F26="Tolerance",IF(-(($E26*3*R26)-Q26)-G26>I26,"",-(($E26*3*R26)-Q26)-G26),IF(F26="MIN",IF(-(($E26*3*R26)-Q26)>I26,"",-(($E26*3*R26)-Q26)),""))) | AB26: =IF(OR(G26="",Q26=""),"",(L26+M26)/2-Q26) | AC26: =IF(OR($S26>$AC$9,$R26=""),"",$AC$9*6*$R26) | AE26: =IF(AD26="","",IF(AD26>=0.966,"Normal","Not Normal"))
A27: 20 | B27: 26 | D27: Distance | F27: Tolerance | G27: 15.262 | H27: 0.03 | I27: -0.03 | J27: OMM | K27: NO | L27: =IF(AND(G27="",H27=""),"",IF(G27="",H27,G27+H27)) -> 15.292 | M27: =IF(AND(G27="",I27=""),"",IF(G27="",I27,G27+I27)) -> 15.232 | O27: =IF(OR($AK27="",ISNUMBER($AK27)=FALSE),"",MAX(AK27:BP27)) | P27: =IF(OR($AK27="",ISNUMBER($AK27)=FALSE),"",MIN(AK27:BP27)) | Q27: =IF(OR($AK27="",ISNUMBER($AK27)=FALSE),"",AVERAGE(AK27:BP27)) | R27: =IF(OR($AK27="",ISNUMBER($AK27)=FALSE),"",STDEV(AK27:BP27)) | S27: =IF(OR($AK27="",ISNUMBER($AK27)=FALSE),"",IF(AND(G27="",I27=""),V27,IF(AND(G27="",H27=""),W27,(H27+ABS(I27))/(6*R27)))) | T27: =IF(OR($AK27="",ISNUMBER($AK27)=FALSE),"",IF(AND($F27="Tolerance",$G27<>""),($Q27-$G27)/(($L27-$M27)/2),IF(AND($F27="GD&T",$H27<>""),$Q27/$H27,""))) | U27: =IF($T27="","",IF(ABS($T27)<=0.125, "Level A",IF(AND(ABS($T27)>0.125,ABS($T27)<=0.25), "Level B",IF(AND(ABS($T27)>0.25,ABS($T27)<=0.5), "Level C", IF(ABS($T27)>0.5, "Level D"))))) | V27: =IF(OR($AK27="",ISNUMBER($AK27)=FALSE),"",IF(H27="","",(L27-Q27)/(3*R27))) | W27: =IF(OR($AK27="",ISNUMBER($AK27)=FALSE),"",IF(I27="","",(Q27-M27)/(3*R27))) | X27: =IF(OR($AK27="",ISNUMBER($AK27)=FALSE),"",IF(AND(G27=0,I27=0),((H27)-(Q27))/(3*R27),MIN(V27:W27))) | Y27: =IF(OR($AK27="",ISNUMBER($AK27)=FALSE),"",IF(AND(G27=0,I27=0),NORMSDIST(3*X27),NORMSDIST(3*X27)+NORMSDIST(6*S27-3*X27)-1)) | Z27: =IF($Q27="","",IF(F27="Tolerance",IF(($E27*3*R27+Q27)-G27<H27,"",($E27*3*R27+Q27)-G27),IF(OR(F27="GD&T",F27="MAX"),IF(($E27*3*R27+Q27)<H27,"",($E27*3*R27+Q27)),""))) | AA27: =IF(Q27="","",IF(F27="Tolerance",IF(-(($E27*3*R27)-Q27)-G27>I27,"",-(($E27*3*R27)-Q27)-G27),IF(F27="MIN",IF(-(($E27*3*R27)-Q27)>I27,"",-(($E27*3*R27)-Q27)),""))) | AB27: =IF(OR(G27="",Q27=""),"",(L27+M27)/2-Q27) | AC27: =IF(OR($S27>$AC$9,$R27=""),"",$AC$9*6*$R27) | AE27: =IF(AD27="","",IF(AD27>=0.966,"Normal","Not Normal"))
A28: 21 | B28: 27 | D28: Distance | F28: Tolerance | G28: 12.839 | H28: 0.03 | I28: -0.03 | J28: OMM | K28: NO | L28: =IF(AND(G28="",H28=""),"",IF(G28="",H28,G28+H28)) -> 12.869 | M28: =IF(AND(G28="",I28=""),"",IF(G28="",I28,G28+I28)) -> 12.809 | O28: =IF(OR($AK28="",ISNUMBER($AK28)=FALSE),"",MAX(AK28:BP28)) | P28: =IF(OR($AK28="",ISNUMBER($AK28)=FALSE),"",MIN(AK28:BP28)) | Q28: =IF(OR($AK28="",ISNUMBER($AK28)=FALSE),"",AVERAGE(AK28:BP28)) | R28: =IF(OR($AK28="",ISNUMBER($AK28)=FALSE),"",STDEV(AK28:BP28)) | S28: =IF(OR($AK28="",ISNUMBER($AK28)=FALSE),"",IF(AND(G28="",I28=""),V28,IF(AND(G28="",H28=""),W28,(H28+ABS(I28))/(6*R28)))) | T28: =IF(OR($AK28="",ISNUMBER($AK28)=FALSE),"",IF(AND($F28="Tolerance",$G28<>""),($Q28-$G28)/(($L28-$M28)/2),IF(AND($F28="GD&T",$H28<>""),$Q28/$H28,""))) | U28: =IF($T28="","",IF(ABS($T28)<=0.125, "Level A",IF(AND(ABS($T28)>0.125,ABS($T28)<=0.25), "Level B",IF(AND(ABS($T28)>0.25,ABS($T28)<=0.5), "Level C", IF(ABS($T28)>0.5, "Level D"))))) | V28: =IF(OR($AK28="",ISNUMBER($AK28)=FALSE),"",IF(H28="","",(L28-Q28)/(3*R28))) | W28: =IF(OR($AK28="",ISNUMBER($AK28)=FALSE),"",IF(I28="","",(Q28-M28)/(3*R28))) | X28: =IF(OR($AK28="",ISNUMBER($AK28)=FALSE),"",IF(AND(G28=0,I28=0),((H28)-(Q28))/(3*R28),MIN(V28:W28))) | Y28: =IF(OR($AK28="",ISNUMBER($AK28)=FALSE),"",IF(AND(G28=0,I28=0),NORMSDIST(3*X28),NORMSDIST(3*X28)+NORMSDIST(6*S28-3*X28)-1)) | Z28: =IF($Q28="","",IF(F28="Tolerance",IF(($E28*3*R28+Q28)-G28<H28,"",($E28*3*R28+Q28)-G28),IF(OR(F28="GD&T",F28="MAX"),IF(($E28*3*R28+Q28)<H28,"",($E28*3*R28+Q28)),""))) | AA28: =IF(Q28="","",IF(F28="Tolerance",IF(-(($E28*3*R28)-Q28)-G28>I28,"",-(($E28*3*R28)-Q28)-G28),IF(F28="MIN",IF(-(($E28*3*R28)-Q28)>I28,"",-(($E28*3*R28)-Q28)),""))) | AB28: =IF(OR(G28="",Q28=""),"",(L28+M28)/2-Q28) | AC28: =IF(OR($S28>$AC$9,$R28=""),"",$AC$9*6*$R28) | AE28: =IF(AD28="","",IF(AD28>=0.966,"Normal","Not Normal"))
A29: 22 | B29: 28 | D29: Distance | F29: Tolerance | G29: 2.627 | H29: 0.03 | I29: -0.03 | J29: OMM | K29: NO | L29: =IF(AND(G29="",H29=""),"",IF(G29="",H29,G29+H29)) -> 2.657 | M29: =IF(AND(G29="",I29=""),"",IF(G29="",I29,G29+I29)) -> 2.597 | O29: =IF(OR($AK29="",ISNUMBER($AK29)=FALSE),"",MAX(AK29:BP29)) | P29: =IF(OR($AK29="",ISNUMBER($AK29)=FALSE),"",MIN(AK29:BP29)) | Q29: =IF(OR($AK29="",ISNUMBER($AK29)=FALSE),"",AVERAGE(AK29:BP29)) | R29: =IF(OR($AK29="",ISNUMBER($AK29)=FALSE),"",STDEV(AK29:BP29)) | S29: =IF(OR($AK29="",ISNUMBER($AK29)=FALSE),"",IF(AND(G29="",I29=""),V29,IF(AND(G29="",H29=""),W29,(H29+ABS(I29))/(6*R29)))) | T29: =IF(OR($AK29="",ISNUMBER($AK29)=FALSE),"",IF(AND($F29="Tolerance",$G29<>""),($Q29-$G29)/(($L29-$M29)/2),IF(AND($F29="GD&T",$H29<>""),$Q29/$H29,""))) | U29: =IF($T29="","",IF(ABS($T29)<=0.125, "Level A",IF(AND(ABS($T29)>0.125,ABS($T29)<=0.25), "Level B",IF(AND(ABS($T29)>0.25,ABS($T29)<=0.5), "Level C", IF(ABS($T29)>0.5, "Level D"))))) | V29: =IF(OR($AK29="",ISNUMBER($AK29)=FALSE),"",IF(H29="","",(L29-Q29)/(3*R29))) | W29: =IF(OR($AK29="",ISNUMBER($AK29)=FALSE),"",IF(I29="","",(Q29-M29)/(3*R29))) | X29: =IF(OR($AK29="",ISNUMBER($AK29)=FALSE),"",IF(AND(G29=0,I29=0),((H29)-(Q29))/(3*R29),MIN(V29:W29))) | Y29: =IF(OR($AK29="",ISNUMBER($AK29)=FALSE),"",IF(AND(G29=0,I29=0),NORMSDIST(3*X29),NORMSDIST(3*X29)+NORMSDIST(6*S29-3*X29)-1)) | Z29: =IF($Q29="","",IF(F29="Tolerance",IF(($E29*3*R29+Q29)-G29<H29,"",($E29*3*R29+Q29)-G29),IF(OR(F29="GD&T",F29="MAX"),IF(($E29*3*R29+Q29)<H29,"",($E29*3*R29+Q29)),""))) | AA29: =IF(Q29="","",IF(F29="Tolerance",IF(-(($E29*3*R29)-Q29)-G29>I29,"",-(($E29*3*R29)-Q29)-G29),IF(F29="MIN",IF(-(($E29*3*R29)-Q29)>I29,"",-(($E29*3*R29)-Q29)),""))) | AB29: =IF(OR(G29="",Q29=""),"",(L29+M29)/2-Q29) | AC29: =IF(OR($S29>$AC$9,$R29=""),"",$AC$9*6*$R29) | AE29: =IF(AD29="","",IF(AD29>=0.966,"Normal","Not Normal"))
A30: 39 | B30: 30 | D30: Distance | F30: Tolerance | G30: 12.482 | H30: 0.03 | I30: -0.03 | J30: OMM | K30: NO | L30: =IF(AND(G30="",H30=""),"",IF(G30="",H30,G30+H30)) -> 12.512 | M30: =IF(AND(G30="",I30=""),"",IF(G30="",I30,G30+I30)) -> 12.452 | O30: =IF(OR($AK30="",ISNUMBER($AK30)=FALSE),"",MAX(AK30:BP30)) | P30: =IF(OR($AK30="",ISNUMBER($AK30)=FALSE),"",MIN(AK30:BP30)) | Q30: =IF(OR($AK30="",ISNUMBER($AK30)=FALSE),"",AVERAGE(AK30:BP30)) | R30: =IF(OR($AK30="",ISNUMBER($AK30)=FALSE),"",STDEV(AK30:BP30)) | S30: =IF(OR($AK30="",ISNUMBER($AK30)=FALSE),"",IF(AND(G30="",I30=""),V30,IF(AND(G30="",H30=""),W30,(H30+ABS(I30))/(6*R30)))) | T30: =IF(OR($AK30="",ISNUMBER($AK30)=FALSE),"",IF(AND($F30="Tolerance",$G30<>""),($Q30-$G30)/(($L30-$M30)/2),IF(AND($F30="GD&T",$H30<>""),$Q30/$H30,""))) | U30: =IF($T30="","",IF(ABS($T30)<=0.125, "Level A",IF(AND(ABS($T30)>0.125,ABS($T30)<=0.25), "Level B",IF(AND(ABS($T30)>0.25,ABS($T30)<=0.5), "Level C", IF(ABS($T30)>0.5, "Level D"))))) | V30: =IF(OR($AK30="",ISNUMBER($AK30)=FALSE),"",IF(H30="","",(L30-Q30)/(3*R30))) | W30: =IF(OR($AK30="",ISNUMBER($AK30)=FALSE),"",IF(I30="","",(Q30-M30)/(3*R30))) | X30: =IF(OR($AK30="",ISNUMBER($AK30)=FALSE),"",IF(AND(G30=0,I30=0),((H30)-(Q30))/(3*R30),MIN(V30:W30))) | Y30: =IF(OR($AK30="",ISNUMBER($AK30)=FALSE),"",IF(AND(G30=0,I30=0),NORMSDIST(3*X30),NORMSDIST(3*X30)+NORMSDIST(6*S30-3*X30)-1)) | Z30: =IF($Q30="","",IF(F30="Tolerance",IF(($E30*3*R30+Q30)-G30<H30,"",($E30*3*R30+Q30)-G30),IF(OR(F30="GD&T",F30="MAX"),IF(($E30*3*R30+Q30)<H30,"",($E30*3*R30+Q30)),""))) | AA30: =IF(Q30="","",IF(F30="Tolerance",IF(-(($E30*3*R30)-Q30)-G30>I30,"",-(($E30*3*R30)-Q30)-G30),IF(F30="MIN",IF(-(($E30*3*R30)-Q30)>I30,"",-(($E30*3*R30)-Q30)),""))) | AB30: =IF(OR(G30="",Q30=""),"",(L30+M30)/2-Q30) | AC30: =IF(OR($S30>$AC$9,$R30=""),"",$AC$9*6*$R30) | AE30: =IF(AD30="","",IF(AD30>=0.966,"Normal","Not Normal"))
A31: 40 | B31: 31 | D31: Distance | F31: Tolerance | G31: 11.089 | H31: 0.03 | I31: -0.03 | J31: OMM | K31: NO | L31: =IF(AND(G31="",H31=""),"",IF(G31="",H31,G31+H31)) -> 11.119 | M31: =IF(AND(G31="",I31=""),"",IF(G31="",I31,G31+I31)) -> 11.059 | O31: =IF(OR($AK31="",ISNUMBER($AK31)=FALSE),"",MAX(AK31:BP31)) | P31: =IF(OR($AK31="",ISNUMBER($AK31)=FALSE),"",MIN(AK31:BP31)) | Q31: =IF(OR($AK31="",ISNUMBER($AK31)=FALSE),"",AVERAGE(AK31:BP31)) | R31: =IF(OR($AK31="",ISNUMBER($AK31)=FALSE),"",STDEV(AK31:BP31)) | S31: =IF(OR($AK31="",ISNUMBER($AK31)=FALSE),"",IF(AND(G31="",I31=""),V31,IF(AND(G31="",H31=""),W31,(H31+ABS(I31))/(6*R31)))) | T31: =IF(OR($AK31="",ISNUMBER($AK31)=FALSE),"",IF(AND($F31="Tolerance",$G31<>""),($Q31-$G31)/(($L31-$M31)/2),IF(AND($F31="GD&T",$H31<>""),$Q31/$H31,""))) | U31: =IF($T31="","",IF(ABS($T31)<=0.125, "Level A",IF(AND(ABS($T31)>0.125,ABS($T31)<=0.25), "Level B",IF(AND(ABS($T31)>0.25,ABS($T31)<=0.5), "Level C", IF(ABS($T31)>0.5, "Level D"))))) | V31: =IF(OR($AK31="",ISNUMBER($AK31)=FALSE),"",IF(H31="","",(L31-Q31)/(3*R31))) | W31: =IF(OR($AK31="",ISNUMBER($AK31)=FALSE),"",IF(I31="","",(Q31-M31)/(3*R31))) | X31: =IF(OR($AK31="",ISNUMBER($AK31)=FALSE),"",IF(AND(G31=0,I31=0),((H31)-(Q31))/(3*R31),MIN(V31:W31))) | Y31: =IF(OR($AK31="",ISNUMBER($AK31)=FALSE),"",IF(AND(G31=0,I31=0),NORMSDIST(3*X31),NORMSDIST(3*X31)+NORMSDIST(6*S31-3*X31)-1)) | Z31: =IF($Q31="","",IF(F31="Tolerance",IF(($E31*3*R31+Q31)-G31<H31,"",($E31*3*R31+Q31)-G31),IF(OR(F31="GD&T",F31="MAX"),IF(($E31*3*R31+Q31)<H31,"",($E31*3*R31+Q31)),""))) | AA31: =IF(Q31="","",IF(F31="Tolerance",IF(-(($E31*3*R31)-Q31)-G31>I31,"",-(($E31*3*R31)-Q31)-G31),IF(F31="MIN",IF(-(($E31*3*R31)-Q31)>I31,"",-(($E31*3*R31)-Q31)),""))) | AB31: =IF(OR(G31="",Q31=""),"",(L31+M31)/2-Q31) | AC31: =IF(OR($S31>$AC$9,$R31=""),"",$AC$9*6*$R31) | AE31: =IF(AD31="","",IF(AD31>=0.966,"Normal","Not Normal"))
A32: 41 | B32: 32 | D32: Distance | F32: Tolerance | G32: 2.092 | H32: 0.03 | I32: -0.03 | J32: OMM | K32: NO | L32: =IF(AND(G32="",H32=""),"",IF(G32="",H32,G32+H32)) -> 2.122 | M32: =IF(AND(G32="",I32=""),"",IF(G32="",I32,G32+I32)) -> 2.062 | O32: =IF(OR($AK32="",ISNUMBER($AK32)=FALSE),"",MAX(AK32:BP32)) | P32: =IF(OR($AK32="",ISNUMBER($AK32)=FALSE),"",MIN(AK32:BP32)) | Q32: =IF(OR($AK32="",ISNUMBER($AK32)=FALSE),"",AVERAGE(AK32:BP32)) | R32: =IF(OR($AK32="",ISNUMBER($AK32)=FALSE),"",STDEV(AK32:BP32)) | S32: =IF(OR($AK32="",ISNUMBER($AK32)=FALSE),"",IF(AND(G32="",I32=""),V32,IF(AND(G32="",H32=""),W32,(H32+ABS(I32))/(6*R32)))) | T32: =IF(OR($AK32="",ISNUMBER($AK32)=FALSE),"",IF(AND($F32="Tolerance",$G32<>""),($Q32-$G32)/(($L32-$M32)/2),IF(AND($F32="GD&T",$H32<>""),$Q32/$H32,""))) | U32: =IF($T32="","",IF(ABS($T32)<=0.125, "Level A",IF(AND(ABS($T32)>0.125,ABS($T32)<=0.25), "Level B",IF(AND(ABS($T32)>0.25,ABS($T32)<=0.5), "Level C", IF(ABS($T32)>0.5, "Level D"))))) | V32: =IF(OR($AK32="",ISNUMBER($AK32)=FALSE),"",IF(H32="","",(L32-Q32)/(3*R32))) | W32: =IF(OR($AK32="",ISNUMBER($AK32)=FALSE),"",IF(I32="","",(Q32-M32)/(3*R32))) | X32: =IF(OR($AK32="",ISNUMBER($AK32)=FALSE),"",IF(AND(G32=0,I32=0),((H32)-(Q32))/(3*R32),MIN(V32:W32))) | Y32: =IF(OR($AK32="",ISNUMBER($AK32)=FALSE),"",IF(AND(G32=0,I32=0),NORMSDIST(3*X32),NORMSDIST(3*X32)+NORMSDIST(6*S32-3*X32)-1)) | Z32: =IF($Q32="","",IF(F32="Tolerance",IF(($E32*3*R32+Q32)-G32<H32,"",($E32*3*R32+Q32)-G32),IF(OR(F32="GD&T",F32="MAX"),IF(($E32*3*R32+Q32)<H32,"",($E32*3*R32+Q32)),""))) | AA32: =IF(Q32="","",IF(F32="Tolerance",IF(-(($E32*3*R32)-Q32)-G32>I32,"",-(($E32*3*R32)-Q32)-G32),IF(F32="MIN",IF(-(($E32*3*R32)-Q32)>I32,"",-(($E32*3*R32)-Q32)),""))) | AB32: =IF(OR(G32="",Q32=""),"",(L32+M32)/2-Q32) | AC32: =IF(OR($S32>$AC$9,$R32=""),"",$AC$9*6*$R32) | AE32: =IF(AD32="","",IF(AD32>=0.966,"Normal","Not Normal"))
A33: 42 | B33: 33 | D33: Distance | F33: GD&T | H33: 0.03 | J33: OMM | K33: NO | L33: =IF(AND(G33="",H33=""),"",IF(G33="",H33,G33+H33)) -> 0.03 | M33: =IF(AND(G33="",I33=""),"",IF(G33="",I33,G33+I33)) | O33: =IF(OR($AK33="",ISNUMBER($AK33)=FALSE),"",MAX(AK33:BP33)) | P33: =IF(OR($AK33="",ISNUMBER($AK33)=FALSE),"",MIN(AK33:BP33)) | Q33: =IF(OR($AK33="",ISNUMBER($AK33)=FALSE),"",AVERAGE(AK33:BP33)) | R33: =IF(OR($AK33="",ISNUMBER($AK33)=FALSE),"",STDEV(AK33:BP33)) | S33: =IF(OR($AK33="",ISNUMBER($AK33)=FALSE),"",IF(AND(G33="",I33=""),V33,IF(AND(G33="",H33=""),W33,(H33+ABS(I33))/(6*R33)))) | T33: =IF(OR($AK33="",ISNUMBER($AK33)=FALSE),"",IF(AND($F33="Tolerance",$G33<>""),($Q33-$G33)/(($L33-$M33)/2),IF(AND($F33="GD&T",$H33<>""),$Q33/$H33,""))) | U33: =IF($T33="","",IF(ABS($T33)<=0.125, "Level A",IF(AND(ABS($T33)>0.125,ABS($T33)<=0.25), "Level B",IF(AND(ABS($T33)>0.25,ABS($T33)<=0.5), "Level C", IF(ABS($T33)>0.5, "Level D"))))) | V33: =IF(OR($AK33="",ISNUMBER($AK33)=FALSE),"",IF(H33="","",(L33-Q33)/(3*R33))) | W33: =IF(OR($AK33="",ISNUMBER($AK33)=FALSE),"",IF(I33="","",(Q33-M33)/(3*R33))) | X33: =IF(OR($AK33="",ISNUMBER($AK33)=FALSE),"",IF(AND(G33=0,I33=0),((H33)-(Q33))/(3*R33),MIN(V33:W33))) | Y33: =IF(OR($AK33="",ISNUMBER($AK33)=FALSE),"",IF(AND(G33=0,I33=0),NORMSDIST(3*X33),NORMSDIST(3*X33)+NORMSDIST(6*S33-3*X33)-1)) | Z33: =IF($Q33="","",IF(F33="Tolerance",IF(($E33*3*R33+Q33)-G33<H33,"",($E33*3*R33+Q33)-G33),IF(OR(F33="GD&T",F33="MAX"),IF(($E33*3*R33+Q33)<H33,"",($E33*3*R33+Q33)),""))) | AA33: =IF(Q33="","",IF(F33="Tolerance",IF(-(($E33*3*R33)-Q33)-G33>I33,"",-(($E33*3*R33)-Q33)-G33),IF(F33="MIN",IF(-(($E33*3*R33)-Q33)>I33,"",-(($E33*3*R33)-Q33)),""))) | AB33: =IF(OR(G33="",Q33=""),"",(L33+M33)/2-Q33) | AC33: =IF(OR($S33>$AC$9,$R33=""),"",$AC$9*6*$R33) | AE33: =IF(AD33="","",IF(AD33>=0.966,"Normal","Not Normal"))
A34: 43 | B34: 34 | D34: Distance | F34: GD&T | H34: 0.02 | J34: OMM | K34: NO | L34: =IF(AND(G34="",H34=""),"",IF(G34="",H34,G34+H34)) -> 0.02 | M34: =IF(AND(G34="",I34=""),"",IF(G34="",I34,G34+I34)) | O34: =IF(OR($AK34="",ISNUMBER($AK34)=FALSE),"",MAX(AK34:BP34)) | P34: =IF(OR($AK34="",ISNUMBER($AK34)=FALSE),"",MIN(AK34:BP34)) | Q34: =IF(OR($AK34="",ISNUMBER($AK34)=FALSE),"",AVERAGE(AK34:BP34)) | R34: =IF(OR($AK34="",ISNUMBER($AK34)=FALSE),"",STDEV(AK34:BP34)) | S34: =IF(OR($AK34="",ISNUMBER($AK34)=FALSE),"",IF(AND(G34="",I34=""),V34,IF(AND(G34="",H34=""),W34,(H34+ABS(I34))/(6*R34)))) | T34: =IF(OR($AK34="",ISNUMBER($AK34)=FALSE),"",IF(AND($F34="Tolerance",$G34<>""),($Q34-$G34)/(($L34-$M34)/2),IF(AND($F34="GD&T",$H34<>""),$Q34/$H34,""))) | U34: =IF($T34="","",IF(ABS($T34)<=0.125, "Level A",IF(AND(ABS($T34)>0.125,ABS($T34)<=0.25), "Level B",IF(AND(ABS($T34)>0.25,ABS($T34)<=0.5), "Level C", IF(ABS($T34)>0.5, "Level D"))))) | V34: =IF(OR($AK34="",ISNUMBER($AK34)=FALSE),"",IF(H34="","",(L34-Q34)/(3*R34))) | W34: =IF(OR($AK34="",ISNUMBER($AK34)=FALSE),"",IF(I34="","",(Q34-M34)/(3*R34))) | X34: =IF(OR($AK34="",ISNUMBER($AK34)=FALSE),"",IF(AND(G34=0,I34=0),((H34)-(Q34))/(3*R34),MIN(V34:W34))) | Y34: =IF(OR($AK34="",ISNUMBER($AK34)=FALSE),"",IF(AND(G34=0,I34=0),NORMSDIST(3*X34),NORMSDIST(3*X34)+NORMSDIST(6*S34-3*X34)-1)) | Z34: =IF($Q34="","",IF(F34="Tolerance",IF(($E34*3*R34+Q34)-G34<H34,"",($E34*3*R34+Q34)-G34),IF(OR(F34="GD&T",F34="MAX"),IF(($E34*3*R34+Q34)<H34,"",($E34*3*R34+Q34)),""))) | AA34: =IF(Q34="","",IF(F34="Tolerance",IF(-(($E34*3*R34)-Q34)-G34>I34,"",-(($E34*3*R34)-Q34)-G34),IF(F34="MIN",IF(-(($E34*3*R34)-Q34)>I34,"",-(($E34*3*R34)-Q34)),""))) | AB34: =IF(OR(G34="",Q34=""),"",(L34+M34)/2-Q34) | AC34: =IF(OR($S34>$AC$9,$R34=""),"",$AC$9*6*$R34) | AE34: =IF(AD34="","",IF(AD34>=0.966,"Normal","Not Normal"))
A35: 44 | B35: 35 | D35: Distance | F35: Tolerance | G35: 13.614 | H35: 0.03 | I35: -0.03 | J35: OMM | K35: NO | L35: =IF(AND(G35="",H35=""),"",IF(G35="",H35,G35+H35)) -> 13.644 | M35: =IF(AND(G35="",I35=""),"",IF(G35="",I35,G35+I35)) -> 13.584 | O35: =IF(OR($AK35="",ISNUMBER($AK35)=FALSE),"",MAX(AK35:BP35)) | P35: =IF(OR($AK35="",ISNUMBER($AK35)=FALSE),"",MIN(AK35:BP35)) | Q35: =IF(OR($AK35="",ISNUMBER($AK35)=FALSE),"",AVERAGE(AK35:BP35)) | R35: =IF(OR($AK35="",ISNUMBER($AK35)=FALSE),"",STDEV(AK35:BP35)) | S35: =IF(OR($AK35="",ISNUMBER($AK35)=FALSE),"",IF(AND(G35="",I35=""),V35,IF(AND(G35="",H35=""),W35,(H35+ABS(I35))/(6*R35)))) | T35: =IF(OR($AK35="",ISNUMBER($AK35)=FALSE),"",IF(AND($F35="Tolerance",$G35<>""),($Q35-$G35)/(($L35-$M35)/2),IF(AND($F35="GD&T",$H35<>""),$Q35/$H35,""))) | U35: =IF($T35="","",IF(ABS($T35)<=0.125, "Level A",IF(AND(ABS($T35)>0.125,ABS($T35)<=0.25), "Level B",IF(AND(ABS($T35)>0.25,ABS($T35)<=0.5), "Level C", IF(ABS($T35)>0.5, "Level D"))))) | V35: =IF(OR($AK35="",ISNUMBER($AK35)=FALSE),"",IF(H35="","",(L35-Q35)/(3*R35))) | W35: =IF(OR($AK35="",ISNUMBER($AK35)=FALSE),"",IF(I35="","",(Q35-M35)/(3*R35))) | X35: =IF(OR($AK35="",ISNUMBER($AK35)=FALSE),"",IF(AND(G35=0,I35=0),((H35)-(Q35))/(3*R35),MIN(V35:W35))) | Y35: =IF(OR($AK35="",ISNUMBER($AK35)=FALSE),"",IF(AND(G35=0,I35=0),NORMSDIST(3*X35),NORMSDIST(3*X35)+NORMSDIST(6*S35-3*X35)-1)) | Z35: =IF($Q35="","",IF(F35="Tolerance",IF(($E35*3*R35+Q35)-G35<H35,"",($E35*3*R35+Q35)-G35),IF(OR(F35="GD&T",F35="MAX"),IF(($E35*3*R35+Q35)<H35,"",($E35*3*R35+Q35)),""))) | AA35: =IF(Q35="","",IF(F35="Tolerance",IF(-(($E35*3*R35)-Q35)-G35>I35,"",-(($E35*3*R35)-Q35)-G35),IF(F35="MIN",IF(-(($E35*3*R35)-Q35)>I35,"",-(($E35*3*R35)-Q35)),""))) | AB35: =IF(OR(G35="",Q35=""),"",(L35+M35)/2-Q35) | AC35: =IF(OR($S35>$AC$9,$R35=""),"",$AC$9*6*$R35) | AE35: =IF(AD35="","",IF(AD35>=0.966,"Normal","Not Normal"))
A36: 45 | B36: 36 | D36: Distance | F36: Tolerance | G36: 1.951 | H36: 0.03 | I36: -0.03 | J36: OMM | K36: NO | L36: =IF(AND(G36="",H36=""),"",IF(G36="",H36,G36+H36)) -> 1.981 | M36: =IF(AND(G36="",I36=""),"",IF(G36="",I36,G36+I36)) -> 1.921 | O36: =IF(OR($AK36="",ISNUMBER($AK36)=FALSE),"",MAX(AK36:BP36)) | P36: =IF(OR($AK36="",ISNUMBER($AK36)=FALSE),"",MIN(AK36:BP36)) | Q36: =IF(OR($AK36="",ISNUMBER($AK36)=FALSE),"",AVERAGE(AK36:BP36)) | R36: =IF(OR($AK36="",ISNUMBER($AK36)=FALSE),"",STDEV(AK36:BP36)) | S36: =IF(OR($AK36="",ISNUMBER($AK36)=FALSE),"",IF(AND(G36="",I36=""),V36,IF(AND(G36="",H36=""),W36,(H36+ABS(I36))/(6*R36)))) | T36: =IF(OR($AK36="",ISNUMBER($AK36)=FALSE),"",IF(AND($F36="Tolerance",$G36<>""),($Q36-$G36)/(($L36-$M36)/2),IF(AND($F36="GD&T",$H36<>""),$Q36/$H36,""))) | U36: =IF($T36="","",IF(ABS($T36)<=0.125, "Level A",IF(AND(ABS($T36)>0.125,ABS($T36)<=0.25), "Level B",IF(AND(ABS($T36)>0.25,ABS($T36)<=0.5), "Level C", IF(ABS($T36)>0.5, "Level D"))))) | V36: =IF(OR($AK36="",ISNUMBER($AK36)=FALSE),"",IF(H36="","",(L36-Q36)/(3*R36))) | W36: =IF(OR($AK36="",ISNUMBER($AK36)=FALSE),"",IF(I36="","",(Q36-M36)/(3*R36))) | X36: =IF(OR($AK36="",ISNUMBER($AK36)=FALSE),"",IF(AND(G36=0,I36=0),((H36)-(Q36))/(3*R36),MIN(V36:W36))) | Y36: =IF(OR($AK36="",ISNUMBER($AK36)=FALSE),"",IF(AND(G36=0,I36=0),NORMSDIST(3*X36),NORMSDIST(3*X36)+NORMSDIST(6*S36-3*X36)-1)) | Z36: =IF($Q36="","",IF(F36="Tolerance",IF(($E36*3*R36+Q36)-G36<H36,"",($E36*3*R36+Q36)-G36),IF(OR(F36="GD&T",F36="MAX"),IF(($E36*3*R36+Q36)<H36,"",($E36*3*R36+Q36)),""))) | AA36: =IF(Q36="","",IF(F36="Tolerance",IF(-(($E36*3*R36)-Q36)-G36>I36,"",-(($E36*3*R36)-Q36)-G36),IF(F36="MIN",IF(-(($E36*3*R36)-Q36)>I36,"",-(($E36*3*R36)-Q36)),""))) | AB36: =IF(OR(G36="",Q36=""),"",(L36+M36)/2-Q36) | AC36: =IF(OR($S36>$AC$9,$R36=""),"",$AC$9*6*$R36) | AE36: =IF(AD36="","",IF(AD36>=0.966,"Normal","Not Normal"))
A37: 46 | B37: 37 | D37: Distance | F37: Tolerance | G37: 2.355 | H37: 0.03 | I37: -0.03 | J37: OMM | K37: NO | L37: =IF(AND(G37="",H37=""),"",IF(G37="",H37,G37+H37)) -> 2.385 | M37: =IF(AND(G37="",I37=""),"",IF(G37="",I37,G37+I37)) -> 2.325 | O37: =IF(OR($AK37="",ISNUMBER($AK37)=FALSE),"",MAX(AK37:BP37)) | P37: =IF(OR($AK37="",ISNUMBER($AK37)=FALSE),"",MIN(AK37:BP37)) | Q37: =IF(OR($AK37="",ISNUMBER($AK37)=FALSE),"",AVERAGE(AK37:BP37)) | R37: =IF(OR($AK37="",ISNUMBER($AK37)=FALSE),"",STDEV(AK37:BP37)) | S37: =IF(OR($AK37="",ISNUMBER($AK37)=FALSE),"",IF(AND(G37="",I37=""),V37,IF(AND(G37="",H37=""),W37,(H37+ABS(I37))/(6*R37)))) | T37: =IF(OR($AK37="",ISNUMBER($AK37)=FALSE),"",IF(AND($F37="Tolerance",$G37<>""),($Q37-$G37)/(($L37-$M37)/2),IF(AND($F37="GD&T",$H37<>""),$Q37/$H37,""))) | U37: =IF($T37="","",IF(ABS($T37)<=0.125, "Level A",IF(AND(ABS($T37)>0.125,ABS($T37)<=0.25), "Level B",IF(AND(ABS($T37)>0.25,ABS($T37)<=0.5), "Level C", IF(ABS($T37)>0.5, "Level D"))))) | V37: =IF(OR($AK37="",ISNUMBER($AK37)=FALSE),"",IF(H37="","",(L37-Q37)/(3*R37))) | W37: =IF(OR($AK37="",ISNUMBER($AK37)=FALSE),"",IF(I37="","",(Q37-M37)/(3*R37))) | X37: =IF(OR($AK37="",ISNUMBER($AK37)=FALSE),"",IF(AND(G37=0,I37=0),((H37)-(Q37))/(3*R37),MIN(V37:W37))) | Y37: =IF(OR($AK37="",ISNUMBER($AK37)=FALSE),"",IF(AND(G37=0,I37=0),NORMSDIST(3*X37),NORMSDIST(3*X37)+NORMSDIST(6*S37-3*X37)-1)) | Z37: =IF($Q37="","",IF(F37="Tolerance",IF(($E37*3*R37+Q37)-G37<H37,"",($E37*3*R37+Q37)-G37),IF(OR(F37="GD&T",F37="MAX"),IF(($E37*3*R37+Q37)<H37,"",($E37*3*R37+Q37)),""))) | AA37: =IF(Q37="","",IF(F37="Tolerance",IF(-(($E37*3*R37)-Q37)-G37>I37,"",-(($E37*3*R37)-Q37)-G37),IF(F37="MIN",IF(-(($E37*3*R37)-Q37)>I37,"",-(($E37*3*R37)-Q37)),""))) | AB37: =IF(OR(G37="",Q37=""),"",(L37+M37)/2-Q37) | AC37: =IF(OR($S37>$AC$9,$R37=""),"",$AC$9*6*$R37) | AE37: =IF(AD37="","",IF(AD37>=0.966,"Normal","Not Normal"))
A38: 47 | B38: 38 | D38: Distance | F38: Tolerance | G38: 10.182 | H38: 0.03 | I38: -0.03 | J38: OMM | K38: NO | L38: =IF(AND(G38="",H38=""),"",IF(G38="",H38,G38+H38)) -> 10.212 | M38: =IF(AND(G38="",I38=""),"",IF(G38="",I38,G38+I38)) -> 10.152 | O38: =IF(OR($AK38="",ISNUMBER($AK38)=FALSE),"",MAX(AK38:BP38)) | P38: =IF(OR($AK38="",ISNUMBER($AK38)=FALSE),"",MIN(AK38:BP38)) | Q38: =IF(OR($AK38="",ISNUMBER($AK38)=FALSE),"",AVERAGE(AK38:BP38)) | R38: =IF(OR($AK38="",ISNUMBER($AK38)=FALSE),"",STDEV(AK38:BP38)) | S38: =IF(OR($AK38="",ISNUMBER($AK38)=FALSE),"",IF(AND(G38="",I38=""),V38,IF(AND(G38="",H38=""),W38,(H38+ABS(I38))/(6*R38)))) | T38: =IF(OR($AK38="",ISNUMBER($AK38)=FALSE),"",IF(AND($F38="Tolerance",$G38<>""),($Q38-$G38)/(($L38-$M38)/2),IF(AND($F38="GD&T",$H38<>""),$Q38/$H38,""))) | U38: =IF($T38="","",IF(ABS($T38)<=0.125, "Level A",IF(AND(ABS($T38)>0.125,ABS($T38)<=0.25), "Level B",IF(AND(ABS($T38)>0.25,ABS($T38)<=0.5), "Level C", IF(ABS($T38)>0.5, "Level D"))))) | V38: =IF(OR($AK38="",ISNUMBER($AK38)=FALSE),"",IF(H38="","",(L38-Q38)/(3*R38))) | W38: =IF(OR($AK38="",ISNUMBER($AK38)=FALSE),"",IF(I38="","",(Q38-M38)/(3*R38))) | X38: =IF(OR($AK38="",ISNUMBER($AK38)=FALSE),"",IF(AND(G38=0,I38=0),((H38)-(Q38))/(3*R38),MIN(V38:W38))) | Y38: =IF(OR($AK38="",ISNUMBER($AK38)=FALSE),"",IF(AND(G38=0,I38=0),NORMSDIST(3*X38),NORMSDIST(3*X38)+NORMSDIST(6*S38-3*X38)-1)) | Z38: =IF($Q38="","",IF(F38="Tolerance",IF(($E38*3*R38+Q38)-G38<H38,"",($E38*3*R38+Q38)-G38),IF(OR(F38="GD&T",F38="MAX"),IF(($E38*3*R38+Q38)<H38,"",($E38*3*R38+Q38)),""))) | AA38: =IF(Q38="","",IF(F38="Tolerance",IF(-(($E38*3*R38)-Q38)-G38>I38,"",-(($E38*3*R38)-Q38)-G38),IF(F38="MIN",IF(-(($E38*3*R38)-Q38)>I38,"",-(($E38*3*R38)-Q38)),""))) | AB38: =IF(OR(G38="",Q38=""),"",(L38+M38)/2-Q38) | AC38: =IF(OR($S38>$AC$9,$R38=""),"",$AC$9*6*$R38) | AE38: =IF(AD38="","",IF(AD38>=0.966,"Normal","Not Normal"))
A39: 48 | B39: 39 | D39: Distance | F39: Tolerance | G39: 0.2 | H39: 0.03 | I39: -0.03 | J39: OMM | K39: NO | L39: =IF(AND(G39="",H39=""),"",IF(G39="",H39,G39+H39)) -> 0.23 | M39: =IF(AND(G39="",I39=""),"",IF(G39="",I39,G39+I39)) -> 0.17 | O39: =IF(OR($AK39="",ISNUMBER($AK39)=FALSE),"",MAX(AK39:BP39)) | P39: =IF(OR($AK39="",ISNUMBER($AK39)=FALSE),"",MIN(AK39:BP39)) | Q39: =IF(OR($AK39="",ISNUMBER($AK39)=FALSE),"",AVERAGE(AK39:BP39)) | R39: =IF(OR($AK39="",ISNUMBER($AK39)=FALSE),"",STDEV(AK39:BP39)) | S39: =IF(OR($AK39="",ISNUMBER($AK39)=FALSE),"",IF(AND(G39="",I39=""),V39,IF(AND(G39="",H39=""),W39,(H39+ABS(I39))/(6*R39)))) | T39: =IF(OR($AK39="",ISNUMBER($AK39)=FALSE),"",IF(AND($F39="Tolerance",$G39<>""),($Q39-$G39)/(($L39-$M39)/2),IF(AND($F39="GD&T",$H39<>""),$Q39/$H39,""))) | U39: =IF($T39="","",IF(ABS($T39)<=0.125, "Level A",IF(AND(ABS($T39)>0.125,ABS($T39)<=0.25), "Level B",IF(AND(ABS($T39)>0.25,ABS($T39)<=0.5), "Level C", IF(ABS($T39)>0.5, "Level D"))))) | V39: =IF(OR($AK39="",ISNUMBER($AK39)=FALSE),"",IF(H39="","",(L39-Q39)/(3*R39))) | W39: =IF(OR($AK39="",ISNUMBER($AK39)=FALSE),"",IF(I39="","",(Q39-M39)/(3*R39))) | X39: =IF(OR($AK39="",ISNUMBER($AK39)=FALSE),"",IF(AND(G39=0,I39=0),((H39)-(Q39))/(3*R39),MIN(V39:W39))) | Y39: =IF(OR($AK39="",ISNUMBER($AK39)=FALSE),"",IF(AND(G39=0,I39=0),NORMSDIST(3*X39),NORMSDIST(3*X39)+NORMSDIST(6*S39-3*X39)-1)) | Z39: =IF($Q39="","",IF(F39="Tolerance",IF(($E39*3*R39+Q39)-G39<H39,"",($E39*3*R39+Q39)-G39),IF(OR(F39="GD&T",F39="MAX"),IF(($E39*3*R39+Q39)<H39,"",($E39*3*R39+Q39)),""))) | AA39: =IF(Q39="","",IF(F39="Tolerance",IF(-(($E39*3*R39)-Q39)-G39>I39,"",-(($E39*3*R39)-Q39)-G39),IF(F39="MIN",IF(-(($E39*3*R39)-Q39)>I39,"",-(($E39*3*R39)-Q39)),""))) | AB39: =IF(OR(G39="",Q39=""),"",(L39+M39)/2-Q39) | AC39: =IF(OR($S39>$AC$9,$R39=""),"",$AC$9*6*$R39) | AE39: =IF(AD39="","",IF(AD39>=0.966,"Normal","Not Normal"))
A40: 49 | B40: 40-1 | D40: Distance | F40: Tolerance | G40: 0.35 | H40: 0.03 | I40: -0.03 | J40: MIC | K40: NO | L40: =IF(AND(G40="",H40=""),"",IF(G40="",H40,G40+H40)) -> 0.38 | M40: =IF(AND(G40="",I40=""),"",IF(G40="",I40,G40+I40)) -> 0.32 | O40: =IF(OR($AK40="",ISNUMBER($AK40)=FALSE),"",MAX(AK40:BP40)) | P40: =IF(OR($AK40="",ISNUMBER($AK40)=FALSE),"",MIN(AK40:BP40)) | Q40: =IF(OR($AK40="",ISNUMBER($AK40)=FALSE),"",AVERAGE(AK40:BP40)) | R40: =IF(OR($AK40="",ISNUMBER($AK40)=FALSE),"",STDEV(AK40:BP40)) | S40: =IF(OR($AK40="",ISNUMBER($AK40)=FALSE),"",IF(AND(G40="",I40=""),V40,IF(AND(G40="",H40=""),W40,(H40+ABS(I40))/(6*R40)))) | T40: =IF(OR($AK40="",ISNUMBER($AK40)=FALSE),"",IF(AND($F40="Tolerance",$G40<>""),($Q40-$G40)/(($L40-$M40)/2),IF(AND($F40="GD&T",$H40<>""),$Q40/$H40,""))) | U40: =IF($T40="","",IF(ABS($T40)<=0.125, "Level A",IF(AND(ABS($T40)>0.125,ABS($T40)<=0.25), "Level B",IF(AND(ABS($T40)>0.25,ABS($T40)<=0.5), "Level C", IF(ABS($T40)>0.5, "Level D"))))) | V40: =IF(OR($AK40="",ISNUMBER($AK40)=FALSE),"",IF(H40="","",(L40-Q40)/(3*R40))) | W40: =IF(OR($AK40="",ISNUMBER($AK40)=FALSE),"",IF(I40="","",(Q40-M40)/(3*R40))) | X40: =IF(OR($AK40="",ISNUMBER($AK40)=FALSE),"",IF(AND(G40=0,I40=0),((H40)-(Q40))/(3*R40),MIN(V40:W40))) | Y40: =IF(OR($AK40="",ISNUMBER($AK40)=FALSE),"",IF(AND(G40=0,I40=0),NORMSDIST(3*X40),NORMSDIST(3*X40)+NORMSDIST(6*S40-3*X40)-1)) | Z40: =IF($Q40="","",IF(F40="Tolerance",IF(($E40*3*R40+Q40)-G40<H40,"",($E40*3*R40+Q40)-G40),IF(OR(F40="GD&T",F40="MAX"),IF(($E40*3*R40+Q40)<H40,"",($E40*3*R40+Q40)),""))) | AA40: =IF(Q40="","",IF(F40="Tolerance",IF(-(($E40*3*R40)-Q40)-G40>I40,"",-(($E40*3*R40)-Q40)-G40),IF(F40="MIN",IF(-(($E40*3*R40)-Q40)>I40,"",-(($E40*3*R40)-Q40)),""))) | AB40: =IF(OR(G40="",Q40=""),"",(L40+M40)/2-Q40) | AC40: =IF(OR($S40>$AC$9,$R40=""),"",$AC$9*6*$R40) | AE40: =IF(AD40="","",IF(AD40>=0.966,"Normal","Not Normal"))
